ERROR 2024-09-23 19:43:44,919 root Unexpected error: Multiple exceptions: [Errno 10061] Connect call failed ('::1', 5432, 0, 0), [Errno 10061] Connect call failed ('127.0.0.1', 5432)
Traceback (most recent call last):
  File "D:\Projects\Fast_API\blog_app\backend\app\core\database.py", line 19, in get_db
    yield session
  File "C:\Users\Admin\AppData\Roaming\Python\Python312\site-packages\fastapi\routing.py", line 278, in app
    raw_response = await run_endpoint_function(
                   ^^^^^^^^^^^^^^^^^^^^^^^^^^^^
  File "C:\Users\Admin\AppData\Roaming\Python\Python312\site-packages\fastapi\routing.py", line 191, in run_endpoint_function
    return await dependant.call(**values)
           ^^^^^^^^^^^^^^^^^^^^^^^^^^^^^^
  File "D:\Projects\Fast_API\blog_app\backend\app\routers\categories.py", line 15, in create_category
    response = await CategoryService.create_categories(
               ^^^^^^^^^^^^^^^^^^^^^^^^^^^^^^^^^^^^^^^^
  File "D:\Projects\Fast_API\blog_app\backend\app\services\categories.py", line 38, in create_categories
    existing_category = await db.execute(select(Category).where(Category.name == name))
                        ^^^^^^^^^^^^^^^^^^^^^^^^^^^^^^^^^^^^^^^^^^^^^^^^^^^^^^^^^^^^^^^
  File "C:\Users\Admin\AppData\Roaming\Python\Python312\site-packages\sqlalchemy\ext\asyncio\session.py", line 461, in execute
    result = await greenlet_spawn(
             ^^^^^^^^^^^^^^^^^^^^^
  File "C:\Users\Admin\AppData\Roaming\Python\Python312\site-packages\sqlalchemy\util\_concurrency_py3k.py", line 201, in greenlet_spawn
    result = context.throw(*sys.exc_info())
             ^^^^^^^^^^^^^^^^^^^^^^^^^^^^^^
  File "C:\Users\Admin\AppData\Roaming\Python\Python312\site-packages\sqlalchemy\orm\session.py", line 2362, in execute
    return self._execute_internal(
           ^^^^^^^^^^^^^^^^^^^^^^^
  File "C:\Users\Admin\AppData\Roaming\Python\Python312\site-packages\sqlalchemy\orm\session.py", line 2237, in _execute_internal
    conn = self._connection_for_bind(bind)
           ^^^^^^^^^^^^^^^^^^^^^^^^^^^^^^^
  File "C:\Users\Admin\AppData\Roaming\Python\Python312\site-packages\sqlalchemy\orm\session.py", line 2106, in _connection_for_bind
    return trans._connection_for_bind(engine, execution_options)
           ^^^^^^^^^^^^^^^^^^^^^^^^^^^^^^^^^^^^^^^^^^^^^^^^^^^^^
  File "<string>", line 2, in _connection_for_bind
  File "C:\Users\Admin\AppData\Roaming\Python\Python312\site-packages\sqlalchemy\orm\state_changes.py", line 139, in _go
    ret_value = fn(self, *arg, **kw)
                ^^^^^^^^^^^^^^^^^^^^
  File "C:\Users\Admin\AppData\Roaming\Python\Python312\site-packages\sqlalchemy\orm\session.py", line 1189, in _connection_for_bind
    conn = bind.connect()
           ^^^^^^^^^^^^^^
  File "C:\Users\Admin\AppData\Roaming\Python\Python312\site-packages\sqlalchemy\engine\base.py", line 3278, in connect
    return self._connection_cls(self)
           ^^^^^^^^^^^^^^^^^^^^^^^^^^
  File "C:\Users\Admin\AppData\Roaming\Python\Python312\site-packages\sqlalchemy\engine\base.py", line 146, in __init__
    self._dbapi_connection = engine.raw_connection()
                             ^^^^^^^^^^^^^^^^^^^^^^^
  File "C:\Users\Admin\AppData\Roaming\Python\Python312\site-packages\sqlalchemy\engine\base.py", line 3302, in raw_connection
    return self.pool.connect()
           ^^^^^^^^^^^^^^^^^^^
  File "C:\Users\Admin\AppData\Roaming\Python\Python312\site-packages\sqlalchemy\pool\base.py", line 449, in connect
    return _ConnectionFairy._checkout(self)
           ^^^^^^^^^^^^^^^^^^^^^^^^^^^^^^^^
  File "C:\Users\Admin\AppData\Roaming\Python\Python312\site-packages\sqlalchemy\pool\base.py", line 1263, in _checkout
    fairy = _ConnectionRecord.checkout(pool)
            ^^^^^^^^^^^^^^^^^^^^^^^^^^^^^^^^
  File "C:\Users\Admin\AppData\Roaming\Python\Python312\site-packages\sqlalchemy\pool\base.py", line 712, in checkout
    rec = pool._do_get()
          ^^^^^^^^^^^^^^
  File "C:\Users\Admin\AppData\Roaming\Python\Python312\site-packages\sqlalchemy\pool\impl.py", line 179, in _do_get
    with util.safe_reraise():
  File "C:\Users\Admin\AppData\Roaming\Python\Python312\site-packages\sqlalchemy\util\langhelpers.py", line 146, in __exit__
    raise exc_value.with_traceback(exc_tb)
  File "C:\Users\Admin\AppData\Roaming\Python\Python312\site-packages\sqlalchemy\pool\impl.py", line 177, in _do_get
    return self._create_connection()
           ^^^^^^^^^^^^^^^^^^^^^^^^^
  File "C:\Users\Admin\AppData\Roaming\Python\Python312\site-packages\sqlalchemy\pool\base.py", line 390, in _create_connection
    return _ConnectionRecord(self)
           ^^^^^^^^^^^^^^^^^^^^^^^
  File "C:\Users\Admin\AppData\Roaming\Python\Python312\site-packages\sqlalchemy\pool\base.py", line 674, in __init__
    self.__connect()
  File "C:\Users\Admin\AppData\Roaming\Python\Python312\site-packages\sqlalchemy\pool\base.py", line 900, in __connect
    with util.safe_reraise():
  File "C:\Users\Admin\AppData\Roaming\Python\Python312\site-packages\sqlalchemy\util\langhelpers.py", line 146, in __exit__
    raise exc_value.with_traceback(exc_tb)
  File "C:\Users\Admin\AppData\Roaming\Python\Python312\site-packages\sqlalchemy\pool\base.py", line 896, in __connect
    self.dbapi_connection = connection = pool._invoke_creator(self)
                                         ^^^^^^^^^^^^^^^^^^^^^^^^^^
  File "C:\Users\Admin\AppData\Roaming\Python\Python312\site-packages\sqlalchemy\engine\create.py", line 643, in connect
    return dialect.connect(*cargs, **cparams)
           ^^^^^^^^^^^^^^^^^^^^^^^^^^^^^^^^^^
  File "C:\Users\Admin\AppData\Roaming\Python\Python312\site-packages\sqlalchemy\engine\default.py", line 621, in connect
    return self.loaded_dbapi.connect(*cargs, **cparams)
           ^^^^^^^^^^^^^^^^^^^^^^^^^^^^^^^^^^^^^^^^^^^^
  File "C:\Users\Admin\AppData\Roaming\Python\Python312\site-packages\sqlalchemy\dialects\postgresql\asyncpg.py", line 953, in connect
    await_only(creator_fn(*arg, **kw)),
    ^^^^^^^^^^^^^^^^^^^^^^^^^^^^^^^^^^
  File "C:\Users\Admin\AppData\Roaming\Python\Python312\site-packages\sqlalchemy\util\_concurrency_py3k.py", line 132, in await_only
    return current.parent.switch(awaitable)  # type: ignore[no-any-return,attr-defined] # noqa: E501
           ^^^^^^^^^^^^^^^^^^^^^^^^^^^^^^^^
  File "C:\Users\Admin\AppData\Roaming\Python\Python312\site-packages\sqlalchemy\util\_concurrency_py3k.py", line 196, in greenlet_spawn
    value = await result
            ^^^^^^^^^^^^
  File "C:\Users\Admin\AppData\Roaming\Python\Python312\site-packages\asyncpg\connection.py", line 2329, in connect
    return await connect_utils._connect(
           ^^^^^^^^^^^^^^^^^^^^^^^^^^^^^
  File "C:\Users\Admin\AppData\Roaming\Python\Python312\site-packages\asyncpg\connect_utils.py", line 1017, in _connect
    raise last_error or exceptions.TargetServerAttributeNotMatched(
  File "C:\Users\Admin\AppData\Roaming\Python\Python312\site-packages\asyncpg\connect_utils.py", line 991, in _connect
    conn = await _connect_addr(
           ^^^^^^^^^^^^^^^^^^^^
  File "C:\Users\Admin\AppData\Roaming\Python\Python312\site-packages\asyncpg\connect_utils.py", line 828, in _connect_addr
    return await __connect_addr(params, True, *args)
           ^^^^^^^^^^^^^^^^^^^^^^^^^^^^^^^^^^^^^^^^^
  File "C:\Users\Admin\AppData\Roaming\Python\Python312\site-packages\asyncpg\connect_utils.py", line 873, in __connect_addr
    tr, pr = await connector
             ^^^^^^^^^^^^^^^
  File "C:\Users\Admin\AppData\Roaming\Python\Python312\site-packages\asyncpg\connect_utils.py", line 744, in _create_ssl_connection
    tr, pr = await loop.create_connection(
             ^^^^^^^^^^^^^^^^^^^^^^^^^^^^^
  File "D:\installed_software\anaconda3\envs\myenv3\Lib\asyncio\base_events.py", line 1130, in create_connection
    raise OSError('Multiple exceptions: {}'.format(
OSError: Multiple exceptions: [Errno 10061] Connect call failed ('::1', 5432, 0, 0), [Errno 10061] Connect call failed ('127.0.0.1', 5432)
ERROR 2024-09-23 20:03:15,583 root Failed to create subcategory: (sqlalchemy.dialects.postgresql.asyncpg.ProgrammingError) <class 'asyncpg.exceptions.UndefinedTableError'>: relation "subcategories" does not exist
[SQL: SELECT subcategories.id, subcategories.category_id, subcategories.subcat_id, subcategories.name, subcategories.is_active, subcategories.created_on, subcategories.updated_on 
FROM subcategories 
WHERE subcategories.name IN ($1::VARCHAR, $2::VARCHAR)]
[parameters: ('Sample Subcategory 1', 'Sample Subcategory 2')]
(Background on this error at: https://sqlalche.me/e/20/f405)
Traceback (most recent call last):
  File "C:\Users\Admin\AppData\Roaming\Python\Python312\site-packages\sqlalchemy\dialects\postgresql\asyncpg.py", line 514, in _prepare_and_execute
    prepared_stmt, attributes = await adapt_connection._prepare(
                                ^^^^^^^^^^^^^^^^^^^^^^^^^^^^^^^^
  File "C:\Users\Admin\AppData\Roaming\Python\Python312\site-packages\sqlalchemy\dialects\postgresql\asyncpg.py", line 760, in _prepare
    prepared_stmt = await self._connection.prepare(
                    ^^^^^^^^^^^^^^^^^^^^^^^^^^^^^^^
  File "C:\Users\Admin\AppData\Roaming\Python\Python312\site-packages\asyncpg\connection.py", line 636, in prepare
    return await self._prepare(
           ^^^^^^^^^^^^^^^^^^^^
  File "C:\Users\Admin\AppData\Roaming\Python\Python312\site-packages\asyncpg\connection.py", line 654, in _prepare
    stmt = await self._get_statement(
           ^^^^^^^^^^^^^^^^^^^^^^^^^^
  File "C:\Users\Admin\AppData\Roaming\Python\Python312\site-packages\asyncpg\connection.py", line 433, in _get_statement
    statement = await self._protocol.prepare(
                ^^^^^^^^^^^^^^^^^^^^^^^^^^^^^
  File "asyncpg\protocol\protocol.pyx", line 166, in prepare
asyncpg.exceptions.UndefinedTableError: relation "subcategories" does not exist

The above exception was the direct cause of the following exception:

Traceback (most recent call last):
  File "C:\Users\Admin\AppData\Roaming\Python\Python312\site-packages\sqlalchemy\engine\base.py", line 1967, in _exec_single_context
    self.dialect.do_execute(
  File "C:\Users\Admin\AppData\Roaming\Python\Python312\site-packages\sqlalchemy\engine\default.py", line 941, in do_execute
    cursor.execute(statement, parameters)
  File "C:\Users\Admin\AppData\Roaming\Python\Python312\site-packages\sqlalchemy\dialects\postgresql\asyncpg.py", line 572, in execute
    self._adapt_connection.await_(
  File "C:\Users\Admin\AppData\Roaming\Python\Python312\site-packages\sqlalchemy\util\_concurrency_py3k.py", line 132, in await_only
    return current.parent.switch(awaitable)  # type: ignore[no-any-return,attr-defined] # noqa: E501
           ^^^^^^^^^^^^^^^^^^^^^^^^^^^^^^^^
  File "C:\Users\Admin\AppData\Roaming\Python\Python312\site-packages\sqlalchemy\util\_concurrency_py3k.py", line 196, in greenlet_spawn
    value = await result
            ^^^^^^^^^^^^
  File "C:\Users\Admin\AppData\Roaming\Python\Python312\site-packages\sqlalchemy\dialects\postgresql\asyncpg.py", line 550, in _prepare_and_execute
    self._handle_exception(error)
  File "C:\Users\Admin\AppData\Roaming\Python\Python312\site-packages\sqlalchemy\dialects\postgresql\asyncpg.py", line 501, in _handle_exception
    self._adapt_connection._handle_exception(error)
  File "C:\Users\Admin\AppData\Roaming\Python\Python312\site-packages\sqlalchemy\dialects\postgresql\asyncpg.py", line 784, in _handle_exception
    raise translated_error from error
sqlalchemy.dialects.postgresql.asyncpg.AsyncAdapt_asyncpg_dbapi.ProgrammingError: <class 'asyncpg.exceptions.UndefinedTableError'>: relation "subcategories" does not exist

The above exception was the direct cause of the following exception:

Traceback (most recent call last):
  File "D:\Projects\Fast_API\blog_app\backend\app\routers\subcategories.py", line 24, in create_subcategory_route
    existing_subcategory = await db.execute(
                           ^^^^^^^^^^^^^^^^^
  File "C:\Users\Admin\AppData\Roaming\Python\Python312\site-packages\sqlalchemy\ext\asyncio\session.py", line 461, in execute
    result = await greenlet_spawn(
             ^^^^^^^^^^^^^^^^^^^^^
  File "C:\Users\Admin\AppData\Roaming\Python\Python312\site-packages\sqlalchemy\util\_concurrency_py3k.py", line 201, in greenlet_spawn
    result = context.throw(*sys.exc_info())
             ^^^^^^^^^^^^^^^^^^^^^^^^^^^^^^
  File "C:\Users\Admin\AppData\Roaming\Python\Python312\site-packages\sqlalchemy\orm\session.py", line 2362, in execute
    return self._execute_internal(
           ^^^^^^^^^^^^^^^^^^^^^^^
  File "C:\Users\Admin\AppData\Roaming\Python\Python312\site-packages\sqlalchemy\orm\session.py", line 2247, in _execute_internal
    result: Result[Any] = compile_state_cls.orm_execute_statement(
                          ^^^^^^^^^^^^^^^^^^^^^^^^^^^^^^^^^^^^^^^^
  File "C:\Users\Admin\AppData\Roaming\Python\Python312\site-packages\sqlalchemy\orm\context.py", line 305, in orm_execute_statement
    result = conn.execute(
             ^^^^^^^^^^^^^
  File "C:\Users\Admin\AppData\Roaming\Python\Python312\site-packages\sqlalchemy\engine\base.py", line 1418, in execute
    return meth(
           ^^^^^
  File "C:\Users\Admin\AppData\Roaming\Python\Python312\site-packages\sqlalchemy\sql\elements.py", line 515, in _execute_on_connection
    return connection._execute_clauseelement(
           ^^^^^^^^^^^^^^^^^^^^^^^^^^^^^^^^^^
  File "C:\Users\Admin\AppData\Roaming\Python\Python312\site-packages\sqlalchemy\engine\base.py", line 1640, in _execute_clauseelement
    ret = self._execute_context(
          ^^^^^^^^^^^^^^^^^^^^^^
  File "C:\Users\Admin\AppData\Roaming\Python\Python312\site-packages\sqlalchemy\engine\base.py", line 1846, in _execute_context
    return self._exec_single_context(
           ^^^^^^^^^^^^^^^^^^^^^^^^^^
  File "C:\Users\Admin\AppData\Roaming\Python\Python312\site-packages\sqlalchemy\engine\base.py", line 1986, in _exec_single_context
    self._handle_dbapi_exception(
  File "C:\Users\Admin\AppData\Roaming\Python\Python312\site-packages\sqlalchemy\engine\base.py", line 2355, in _handle_dbapi_exception
    raise sqlalchemy_exception.with_traceback(exc_info[2]) from e
  File "C:\Users\Admin\AppData\Roaming\Python\Python312\site-packages\sqlalchemy\engine\base.py", line 1967, in _exec_single_context
    self.dialect.do_execute(
  File "C:\Users\Admin\AppData\Roaming\Python\Python312\site-packages\sqlalchemy\engine\default.py", line 941, in do_execute
    cursor.execute(statement, parameters)
  File "C:\Users\Admin\AppData\Roaming\Python\Python312\site-packages\sqlalchemy\dialects\postgresql\asyncpg.py", line 572, in execute
    self._adapt_connection.await_(
  File "C:\Users\Admin\AppData\Roaming\Python\Python312\site-packages\sqlalchemy\util\_concurrency_py3k.py", line 132, in await_only
    return current.parent.switch(awaitable)  # type: ignore[no-any-return,attr-defined] # noqa: E501
           ^^^^^^^^^^^^^^^^^^^^^^^^^^^^^^^^
  File "C:\Users\Admin\AppData\Roaming\Python\Python312\site-packages\sqlalchemy\util\_concurrency_py3k.py", line 196, in greenlet_spawn
    value = await result
            ^^^^^^^^^^^^
  File "C:\Users\Admin\AppData\Roaming\Python\Python312\site-packages\sqlalchemy\dialects\postgresql\asyncpg.py", line 550, in _prepare_and_execute
    self._handle_exception(error)
  File "C:\Users\Admin\AppData\Roaming\Python\Python312\site-packages\sqlalchemy\dialects\postgresql\asyncpg.py", line 501, in _handle_exception
    self._adapt_connection._handle_exception(error)
  File "C:\Users\Admin\AppData\Roaming\Python\Python312\site-packages\sqlalchemy\dialects\postgresql\asyncpg.py", line 784, in _handle_exception
    raise translated_error from error
sqlalchemy.exc.ProgrammingError: (sqlalchemy.dialects.postgresql.asyncpg.ProgrammingError) <class 'asyncpg.exceptions.UndefinedTableError'>: relation "subcategories" does not exist
[SQL: SELECT subcategories.id, subcategories.category_id, subcategories.subcat_id, subcategories.name, subcategories.is_active, subcategories.created_on, subcategories.updated_on 
FROM subcategories 
WHERE subcategories.name IN ($1::VARCHAR, $2::VARCHAR)]
[parameters: ('Sample Subcategory 1', 'Sample Subcategory 2')]
(Background on this error at: https://sqlalche.me/e/20/f405)
ERROR 2024-09-23 20:03:15,755 root Unexpected error: 500: Failed to create subcategory
Traceback (most recent call last):
  File "C:\Users\Admin\AppData\Roaming\Python\Python312\site-packages\sqlalchemy\dialects\postgresql\asyncpg.py", line 514, in _prepare_and_execute
    prepared_stmt, attributes = await adapt_connection._prepare(
                                ^^^^^^^^^^^^^^^^^^^^^^^^^^^^^^^^
  File "C:\Users\Admin\AppData\Roaming\Python\Python312\site-packages\sqlalchemy\dialects\postgresql\asyncpg.py", line 760, in _prepare
    prepared_stmt = await self._connection.prepare(
                    ^^^^^^^^^^^^^^^^^^^^^^^^^^^^^^^
  File "C:\Users\Admin\AppData\Roaming\Python\Python312\site-packages\asyncpg\connection.py", line 636, in prepare
    return await self._prepare(
           ^^^^^^^^^^^^^^^^^^^^
  File "C:\Users\Admin\AppData\Roaming\Python\Python312\site-packages\asyncpg\connection.py", line 654, in _prepare
    stmt = await self._get_statement(
           ^^^^^^^^^^^^^^^^^^^^^^^^^^
  File "C:\Users\Admin\AppData\Roaming\Python\Python312\site-packages\asyncpg\connection.py", line 433, in _get_statement
    statement = await self._protocol.prepare(
                ^^^^^^^^^^^^^^^^^^^^^^^^^^^^^
  File "asyncpg\protocol\protocol.pyx", line 166, in prepare
asyncpg.exceptions.UndefinedTableError: relation "subcategories" does not exist

The above exception was the direct cause of the following exception:

Traceback (most recent call last):
  File "C:\Users\Admin\AppData\Roaming\Python\Python312\site-packages\sqlalchemy\engine\base.py", line 1967, in _exec_single_context
    self.dialect.do_execute(
  File "C:\Users\Admin\AppData\Roaming\Python\Python312\site-packages\sqlalchemy\engine\default.py", line 941, in do_execute
    cursor.execute(statement, parameters)
  File "C:\Users\Admin\AppData\Roaming\Python\Python312\site-packages\sqlalchemy\dialects\postgresql\asyncpg.py", line 572, in execute
    self._adapt_connection.await_(
  File "C:\Users\Admin\AppData\Roaming\Python\Python312\site-packages\sqlalchemy\util\_concurrency_py3k.py", line 132, in await_only
    return current.parent.switch(awaitable)  # type: ignore[no-any-return,attr-defined] # noqa: E501
           ^^^^^^^^^^^^^^^^^^^^^^^^^^^^^^^^
  File "C:\Users\Admin\AppData\Roaming\Python\Python312\site-packages\sqlalchemy\util\_concurrency_py3k.py", line 196, in greenlet_spawn
    value = await result
            ^^^^^^^^^^^^
  File "C:\Users\Admin\AppData\Roaming\Python\Python312\site-packages\sqlalchemy\dialects\postgresql\asyncpg.py", line 550, in _prepare_and_execute
    self._handle_exception(error)
  File "C:\Users\Admin\AppData\Roaming\Python\Python312\site-packages\sqlalchemy\dialects\postgresql\asyncpg.py", line 501, in _handle_exception
    self._adapt_connection._handle_exception(error)
  File "C:\Users\Admin\AppData\Roaming\Python\Python312\site-packages\sqlalchemy\dialects\postgresql\asyncpg.py", line 784, in _handle_exception
    raise translated_error from error
sqlalchemy.dialects.postgresql.asyncpg.AsyncAdapt_asyncpg_dbapi.ProgrammingError: <class 'asyncpg.exceptions.UndefinedTableError'>: relation "subcategories" does not exist

The above exception was the direct cause of the following exception:

Traceback (most recent call last):
  File "D:\Projects\Fast_API\blog_app\backend\app\routers\subcategories.py", line 24, in create_subcategory_route
    existing_subcategory = await db.execute(
                           ^^^^^^^^^^^^^^^^^
  File "C:\Users\Admin\AppData\Roaming\Python\Python312\site-packages\sqlalchemy\ext\asyncio\session.py", line 461, in execute
    result = await greenlet_spawn(
             ^^^^^^^^^^^^^^^^^^^^^
  File "C:\Users\Admin\AppData\Roaming\Python\Python312\site-packages\sqlalchemy\util\_concurrency_py3k.py", line 201, in greenlet_spawn
    result = context.throw(*sys.exc_info())
             ^^^^^^^^^^^^^^^^^^^^^^^^^^^^^^
  File "C:\Users\Admin\AppData\Roaming\Python\Python312\site-packages\sqlalchemy\orm\session.py", line 2362, in execute
    return self._execute_internal(
           ^^^^^^^^^^^^^^^^^^^^^^^
  File "C:\Users\Admin\AppData\Roaming\Python\Python312\site-packages\sqlalchemy\orm\session.py", line 2247, in _execute_internal
    result: Result[Any] = compile_state_cls.orm_execute_statement(
                          ^^^^^^^^^^^^^^^^^^^^^^^^^^^^^^^^^^^^^^^^
  File "C:\Users\Admin\AppData\Roaming\Python\Python312\site-packages\sqlalchemy\orm\context.py", line 305, in orm_execute_statement
    result = conn.execute(
             ^^^^^^^^^^^^^
  File "C:\Users\Admin\AppData\Roaming\Python\Python312\site-packages\sqlalchemy\engine\base.py", line 1418, in execute
    return meth(
           ^^^^^
  File "C:\Users\Admin\AppData\Roaming\Python\Python312\site-packages\sqlalchemy\sql\elements.py", line 515, in _execute_on_connection
    return connection._execute_clauseelement(
           ^^^^^^^^^^^^^^^^^^^^^^^^^^^^^^^^^^
  File "C:\Users\Admin\AppData\Roaming\Python\Python312\site-packages\sqlalchemy\engine\base.py", line 1640, in _execute_clauseelement
    ret = self._execute_context(
          ^^^^^^^^^^^^^^^^^^^^^^
  File "C:\Users\Admin\AppData\Roaming\Python\Python312\site-packages\sqlalchemy\engine\base.py", line 1846, in _execute_context
    return self._exec_single_context(
           ^^^^^^^^^^^^^^^^^^^^^^^^^^
  File "C:\Users\Admin\AppData\Roaming\Python\Python312\site-packages\sqlalchemy\engine\base.py", line 1986, in _exec_single_context
    self._handle_dbapi_exception(
  File "C:\Users\Admin\AppData\Roaming\Python\Python312\site-packages\sqlalchemy\engine\base.py", line 2355, in _handle_dbapi_exception
    raise sqlalchemy_exception.with_traceback(exc_info[2]) from e
  File "C:\Users\Admin\AppData\Roaming\Python\Python312\site-packages\sqlalchemy\engine\base.py", line 1967, in _exec_single_context
    self.dialect.do_execute(
  File "C:\Users\Admin\AppData\Roaming\Python\Python312\site-packages\sqlalchemy\engine\default.py", line 941, in do_execute
    cursor.execute(statement, parameters)
  File "C:\Users\Admin\AppData\Roaming\Python\Python312\site-packages\sqlalchemy\dialects\postgresql\asyncpg.py", line 572, in execute
    self._adapt_connection.await_(
  File "C:\Users\Admin\AppData\Roaming\Python\Python312\site-packages\sqlalchemy\util\_concurrency_py3k.py", line 132, in await_only
    return current.parent.switch(awaitable)  # type: ignore[no-any-return,attr-defined] # noqa: E501
           ^^^^^^^^^^^^^^^^^^^^^^^^^^^^^^^^
  File "C:\Users\Admin\AppData\Roaming\Python\Python312\site-packages\sqlalchemy\util\_concurrency_py3k.py", line 196, in greenlet_spawn
    value = await result
            ^^^^^^^^^^^^
  File "C:\Users\Admin\AppData\Roaming\Python\Python312\site-packages\sqlalchemy\dialects\postgresql\asyncpg.py", line 550, in _prepare_and_execute
    self._handle_exception(error)
  File "C:\Users\Admin\AppData\Roaming\Python\Python312\site-packages\sqlalchemy\dialects\postgresql\asyncpg.py", line 501, in _handle_exception
    self._adapt_connection._handle_exception(error)
  File "C:\Users\Admin\AppData\Roaming\Python\Python312\site-packages\sqlalchemy\dialects\postgresql\asyncpg.py", line 784, in _handle_exception
    raise translated_error from error
sqlalchemy.exc.ProgrammingError: (sqlalchemy.dialects.postgresql.asyncpg.ProgrammingError) <class 'asyncpg.exceptions.UndefinedTableError'>: relation "subcategories" does not exist
[SQL: SELECT subcategories.id, subcategories.category_id, subcategories.subcat_id, subcategories.name, subcategories.is_active, subcategories.created_on, subcategories.updated_on 
FROM subcategories 
WHERE subcategories.name IN ($1::VARCHAR, $2::VARCHAR)]
[parameters: ('Sample Subcategory 1', 'Sample Subcategory 2')]
(Background on this error at: https://sqlalche.me/e/20/f405)

During handling of the above exception, another exception occurred:

Traceback (most recent call last):
  File "D:\Projects\Fast_API\blog_app\backend\app\core\database.py", line 19, in get_db
    yield session
  File "C:\Users\Admin\AppData\Roaming\Python\Python312\site-packages\fastapi\routing.py", line 278, in app
    raw_response = await run_endpoint_function(
                   ^^^^^^^^^^^^^^^^^^^^^^^^^^^^
  File "C:\Users\Admin\AppData\Roaming\Python\Python312\site-packages\fastapi\routing.py", line 191, in run_endpoint_function
    return await dependant.call(**values)
           ^^^^^^^^^^^^^^^^^^^^^^^^^^^^^^
  File "D:\Projects\Fast_API\blog_app\backend\app\routers\subcategories.py", line 42, in create_subcategory_route
    raise HTTPException(
fastapi.exceptions.HTTPException: 500: Failed to create subcategory
ERROR 2024-09-23 20:12:19,749 root Failed to create subcategory: (sqlalchemy.dialects.postgresql.asyncpg.ProgrammingError) <class 'asyncpg.exceptions.UndefinedTableError'>: relation "subcategories" does not exist
[SQL: SELECT subcategories.id, subcategories.category_id, subcategories.subcat_id, subcategories.name, subcategories.is_active, subcategories.created_on, subcategories.updated_on 
FROM subcategories 
WHERE subcategories.name IN ($1::VARCHAR, $2::VARCHAR)]
[parameters: ('Sample Subcategory 1', 'Sample Subcategory 2')]
(Background on this error at: https://sqlalche.me/e/20/f405)
Traceback (most recent call last):
  File "C:\Users\Admin\AppData\Roaming\Python\Python312\site-packages\sqlalchemy\dialects\postgresql\asyncpg.py", line 514, in _prepare_and_execute
    prepared_stmt, attributes = await adapt_connection._prepare(
                                ^^^^^^^^^^^^^^^^^^^^^^^^^^^^^^^^
  File "C:\Users\Admin\AppData\Roaming\Python\Python312\site-packages\sqlalchemy\dialects\postgresql\asyncpg.py", line 760, in _prepare
    prepared_stmt = await self._connection.prepare(
                    ^^^^^^^^^^^^^^^^^^^^^^^^^^^^^^^
  File "C:\Users\Admin\AppData\Roaming\Python\Python312\site-packages\asyncpg\connection.py", line 636, in prepare
    return await self._prepare(
           ^^^^^^^^^^^^^^^^^^^^
  File "C:\Users\Admin\AppData\Roaming\Python\Python312\site-packages\asyncpg\connection.py", line 654, in _prepare
    stmt = await self._get_statement(
           ^^^^^^^^^^^^^^^^^^^^^^^^^^
  File "C:\Users\Admin\AppData\Roaming\Python\Python312\site-packages\asyncpg\connection.py", line 433, in _get_statement
    statement = await self._protocol.prepare(
                ^^^^^^^^^^^^^^^^^^^^^^^^^^^^^
  File "asyncpg\protocol\protocol.pyx", line 166, in prepare
asyncpg.exceptions.UndefinedTableError: relation "subcategories" does not exist

The above exception was the direct cause of the following exception:

Traceback (most recent call last):
  File "C:\Users\Admin\AppData\Roaming\Python\Python312\site-packages\sqlalchemy\engine\base.py", line 1967, in _exec_single_context
    self.dialect.do_execute(
  File "C:\Users\Admin\AppData\Roaming\Python\Python312\site-packages\sqlalchemy\engine\default.py", line 941, in do_execute
    cursor.execute(statement, parameters)
  File "C:\Users\Admin\AppData\Roaming\Python\Python312\site-packages\sqlalchemy\dialects\postgresql\asyncpg.py", line 572, in execute
    self._adapt_connection.await_(
  File "C:\Users\Admin\AppData\Roaming\Python\Python312\site-packages\sqlalchemy\util\_concurrency_py3k.py", line 132, in await_only
    return current.parent.switch(awaitable)  # type: ignore[no-any-return,attr-defined] # noqa: E501
           ^^^^^^^^^^^^^^^^^^^^^^^^^^^^^^^^
  File "C:\Users\Admin\AppData\Roaming\Python\Python312\site-packages\sqlalchemy\util\_concurrency_py3k.py", line 196, in greenlet_spawn
    value = await result
            ^^^^^^^^^^^^
  File "C:\Users\Admin\AppData\Roaming\Python\Python312\site-packages\sqlalchemy\dialects\postgresql\asyncpg.py", line 550, in _prepare_and_execute
    self._handle_exception(error)
  File "C:\Users\Admin\AppData\Roaming\Python\Python312\site-packages\sqlalchemy\dialects\postgresql\asyncpg.py", line 501, in _handle_exception
    self._adapt_connection._handle_exception(error)
  File "C:\Users\Admin\AppData\Roaming\Python\Python312\site-packages\sqlalchemy\dialects\postgresql\asyncpg.py", line 784, in _handle_exception
    raise translated_error from error
sqlalchemy.dialects.postgresql.asyncpg.AsyncAdapt_asyncpg_dbapi.ProgrammingError: <class 'asyncpg.exceptions.UndefinedTableError'>: relation "subcategories" does not exist

The above exception was the direct cause of the following exception:

Traceback (most recent call last):
  File "D:\Projects\Fast_API\blog_app\backend\app\routers\subcategories.py", line 24, in create_subcategory_route
    existing_subcategory = await db.execute(
                           ^^^^^^^^^^^^^^^^^
  File "C:\Users\Admin\AppData\Roaming\Python\Python312\site-packages\sqlalchemy\ext\asyncio\session.py", line 461, in execute
    result = await greenlet_spawn(
             ^^^^^^^^^^^^^^^^^^^^^
  File "C:\Users\Admin\AppData\Roaming\Python\Python312\site-packages\sqlalchemy\util\_concurrency_py3k.py", line 201, in greenlet_spawn
    result = context.throw(*sys.exc_info())
             ^^^^^^^^^^^^^^^^^^^^^^^^^^^^^^
  File "C:\Users\Admin\AppData\Roaming\Python\Python312\site-packages\sqlalchemy\orm\session.py", line 2362, in execute
    return self._execute_internal(
           ^^^^^^^^^^^^^^^^^^^^^^^
  File "C:\Users\Admin\AppData\Roaming\Python\Python312\site-packages\sqlalchemy\orm\session.py", line 2247, in _execute_internal
    result: Result[Any] = compile_state_cls.orm_execute_statement(
                          ^^^^^^^^^^^^^^^^^^^^^^^^^^^^^^^^^^^^^^^^
  File "C:\Users\Admin\AppData\Roaming\Python\Python312\site-packages\sqlalchemy\orm\context.py", line 305, in orm_execute_statement
    result = conn.execute(
             ^^^^^^^^^^^^^
  File "C:\Users\Admin\AppData\Roaming\Python\Python312\site-packages\sqlalchemy\engine\base.py", line 1418, in execute
    return meth(
           ^^^^^
  File "C:\Users\Admin\AppData\Roaming\Python\Python312\site-packages\sqlalchemy\sql\elements.py", line 515, in _execute_on_connection
    return connection._execute_clauseelement(
           ^^^^^^^^^^^^^^^^^^^^^^^^^^^^^^^^^^
  File "C:\Users\Admin\AppData\Roaming\Python\Python312\site-packages\sqlalchemy\engine\base.py", line 1640, in _execute_clauseelement
    ret = self._execute_context(
          ^^^^^^^^^^^^^^^^^^^^^^
  File "C:\Users\Admin\AppData\Roaming\Python\Python312\site-packages\sqlalchemy\engine\base.py", line 1846, in _execute_context
    return self._exec_single_context(
           ^^^^^^^^^^^^^^^^^^^^^^^^^^
  File "C:\Users\Admin\AppData\Roaming\Python\Python312\site-packages\sqlalchemy\engine\base.py", line 1986, in _exec_single_context
    self._handle_dbapi_exception(
  File "C:\Users\Admin\AppData\Roaming\Python\Python312\site-packages\sqlalchemy\engine\base.py", line 2355, in _handle_dbapi_exception
    raise sqlalchemy_exception.with_traceback(exc_info[2]) from e
  File "C:\Users\Admin\AppData\Roaming\Python\Python312\site-packages\sqlalchemy\engine\base.py", line 1967, in _exec_single_context
    self.dialect.do_execute(
  File "C:\Users\Admin\AppData\Roaming\Python\Python312\site-packages\sqlalchemy\engine\default.py", line 941, in do_execute
    cursor.execute(statement, parameters)
  File "C:\Users\Admin\AppData\Roaming\Python\Python312\site-packages\sqlalchemy\dialects\postgresql\asyncpg.py", line 572, in execute
    self._adapt_connection.await_(
  File "C:\Users\Admin\AppData\Roaming\Python\Python312\site-packages\sqlalchemy\util\_concurrency_py3k.py", line 132, in await_only
    return current.parent.switch(awaitable)  # type: ignore[no-any-return,attr-defined] # noqa: E501
           ^^^^^^^^^^^^^^^^^^^^^^^^^^^^^^^^
  File "C:\Users\Admin\AppData\Roaming\Python\Python312\site-packages\sqlalchemy\util\_concurrency_py3k.py", line 196, in greenlet_spawn
    value = await result
            ^^^^^^^^^^^^
  File "C:\Users\Admin\AppData\Roaming\Python\Python312\site-packages\sqlalchemy\dialects\postgresql\asyncpg.py", line 550, in _prepare_and_execute
    self._handle_exception(error)
  File "C:\Users\Admin\AppData\Roaming\Python\Python312\site-packages\sqlalchemy\dialects\postgresql\asyncpg.py", line 501, in _handle_exception
    self._adapt_connection._handle_exception(error)
  File "C:\Users\Admin\AppData\Roaming\Python\Python312\site-packages\sqlalchemy\dialects\postgresql\asyncpg.py", line 784, in _handle_exception
    raise translated_error from error
sqlalchemy.exc.ProgrammingError: (sqlalchemy.dialects.postgresql.asyncpg.ProgrammingError) <class 'asyncpg.exceptions.UndefinedTableError'>: relation "subcategories" does not exist
[SQL: SELECT subcategories.id, subcategories.category_id, subcategories.subcat_id, subcategories.name, subcategories.is_active, subcategories.created_on, subcategories.updated_on 
FROM subcategories 
WHERE subcategories.name IN ($1::VARCHAR, $2::VARCHAR)]
[parameters: ('Sample Subcategory 1', 'Sample Subcategory 2')]
(Background on this error at: https://sqlalche.me/e/20/f405)
ERROR 2024-09-23 20:12:19,785 root Unexpected error: 500: Failed to create subcategory
Traceback (most recent call last):
  File "C:\Users\Admin\AppData\Roaming\Python\Python312\site-packages\sqlalchemy\dialects\postgresql\asyncpg.py", line 514, in _prepare_and_execute
    prepared_stmt, attributes = await adapt_connection._prepare(
                                ^^^^^^^^^^^^^^^^^^^^^^^^^^^^^^^^
  File "C:\Users\Admin\AppData\Roaming\Python\Python312\site-packages\sqlalchemy\dialects\postgresql\asyncpg.py", line 760, in _prepare
    prepared_stmt = await self._connection.prepare(
                    ^^^^^^^^^^^^^^^^^^^^^^^^^^^^^^^
  File "C:\Users\Admin\AppData\Roaming\Python\Python312\site-packages\asyncpg\connection.py", line 636, in prepare
    return await self._prepare(
           ^^^^^^^^^^^^^^^^^^^^
  File "C:\Users\Admin\AppData\Roaming\Python\Python312\site-packages\asyncpg\connection.py", line 654, in _prepare
    stmt = await self._get_statement(
           ^^^^^^^^^^^^^^^^^^^^^^^^^^
  File "C:\Users\Admin\AppData\Roaming\Python\Python312\site-packages\asyncpg\connection.py", line 433, in _get_statement
    statement = await self._protocol.prepare(
                ^^^^^^^^^^^^^^^^^^^^^^^^^^^^^
  File "asyncpg\protocol\protocol.pyx", line 166, in prepare
asyncpg.exceptions.UndefinedTableError: relation "subcategories" does not exist

The above exception was the direct cause of the following exception:

Traceback (most recent call last):
  File "C:\Users\Admin\AppData\Roaming\Python\Python312\site-packages\sqlalchemy\engine\base.py", line 1967, in _exec_single_context
    self.dialect.do_execute(
  File "C:\Users\Admin\AppData\Roaming\Python\Python312\site-packages\sqlalchemy\engine\default.py", line 941, in do_execute
    cursor.execute(statement, parameters)
  File "C:\Users\Admin\AppData\Roaming\Python\Python312\site-packages\sqlalchemy\dialects\postgresql\asyncpg.py", line 572, in execute
    self._adapt_connection.await_(
  File "C:\Users\Admin\AppData\Roaming\Python\Python312\site-packages\sqlalchemy\util\_concurrency_py3k.py", line 132, in await_only
    return current.parent.switch(awaitable)  # type: ignore[no-any-return,attr-defined] # noqa: E501
           ^^^^^^^^^^^^^^^^^^^^^^^^^^^^^^^^
  File "C:\Users\Admin\AppData\Roaming\Python\Python312\site-packages\sqlalchemy\util\_concurrency_py3k.py", line 196, in greenlet_spawn
    value = await result
            ^^^^^^^^^^^^
  File "C:\Users\Admin\AppData\Roaming\Python\Python312\site-packages\sqlalchemy\dialects\postgresql\asyncpg.py", line 550, in _prepare_and_execute
    self._handle_exception(error)
  File "C:\Users\Admin\AppData\Roaming\Python\Python312\site-packages\sqlalchemy\dialects\postgresql\asyncpg.py", line 501, in _handle_exception
    self._adapt_connection._handle_exception(error)
  File "C:\Users\Admin\AppData\Roaming\Python\Python312\site-packages\sqlalchemy\dialects\postgresql\asyncpg.py", line 784, in _handle_exception
    raise translated_error from error
sqlalchemy.dialects.postgresql.asyncpg.AsyncAdapt_asyncpg_dbapi.ProgrammingError: <class 'asyncpg.exceptions.UndefinedTableError'>: relation "subcategories" does not exist

The above exception was the direct cause of the following exception:

Traceback (most recent call last):
  File "D:\Projects\Fast_API\blog_app\backend\app\routers\subcategories.py", line 24, in create_subcategory_route
    existing_subcategory = await db.execute(
                           ^^^^^^^^^^^^^^^^^
  File "C:\Users\Admin\AppData\Roaming\Python\Python312\site-packages\sqlalchemy\ext\asyncio\session.py", line 461, in execute
    result = await greenlet_spawn(
             ^^^^^^^^^^^^^^^^^^^^^
  File "C:\Users\Admin\AppData\Roaming\Python\Python312\site-packages\sqlalchemy\util\_concurrency_py3k.py", line 201, in greenlet_spawn
    result = context.throw(*sys.exc_info())
             ^^^^^^^^^^^^^^^^^^^^^^^^^^^^^^
  File "C:\Users\Admin\AppData\Roaming\Python\Python312\site-packages\sqlalchemy\orm\session.py", line 2362, in execute
    return self._execute_internal(
           ^^^^^^^^^^^^^^^^^^^^^^^
  File "C:\Users\Admin\AppData\Roaming\Python\Python312\site-packages\sqlalchemy\orm\session.py", line 2247, in _execute_internal
    result: Result[Any] = compile_state_cls.orm_execute_statement(
                          ^^^^^^^^^^^^^^^^^^^^^^^^^^^^^^^^^^^^^^^^
  File "C:\Users\Admin\AppData\Roaming\Python\Python312\site-packages\sqlalchemy\orm\context.py", line 305, in orm_execute_statement
    result = conn.execute(
             ^^^^^^^^^^^^^
  File "C:\Users\Admin\AppData\Roaming\Python\Python312\site-packages\sqlalchemy\engine\base.py", line 1418, in execute
    return meth(
           ^^^^^
  File "C:\Users\Admin\AppData\Roaming\Python\Python312\site-packages\sqlalchemy\sql\elements.py", line 515, in _execute_on_connection
    return connection._execute_clauseelement(
           ^^^^^^^^^^^^^^^^^^^^^^^^^^^^^^^^^^
  File "C:\Users\Admin\AppData\Roaming\Python\Python312\site-packages\sqlalchemy\engine\base.py", line 1640, in _execute_clauseelement
    ret = self._execute_context(
          ^^^^^^^^^^^^^^^^^^^^^^
  File "C:\Users\Admin\AppData\Roaming\Python\Python312\site-packages\sqlalchemy\engine\base.py", line 1846, in _execute_context
    return self._exec_single_context(
           ^^^^^^^^^^^^^^^^^^^^^^^^^^
  File "C:\Users\Admin\AppData\Roaming\Python\Python312\site-packages\sqlalchemy\engine\base.py", line 1986, in _exec_single_context
    self._handle_dbapi_exception(
  File "C:\Users\Admin\AppData\Roaming\Python\Python312\site-packages\sqlalchemy\engine\base.py", line 2355, in _handle_dbapi_exception
    raise sqlalchemy_exception.with_traceback(exc_info[2]) from e
  File "C:\Users\Admin\AppData\Roaming\Python\Python312\site-packages\sqlalchemy\engine\base.py", line 1967, in _exec_single_context
    self.dialect.do_execute(
  File "C:\Users\Admin\AppData\Roaming\Python\Python312\site-packages\sqlalchemy\engine\default.py", line 941, in do_execute
    cursor.execute(statement, parameters)
  File "C:\Users\Admin\AppData\Roaming\Python\Python312\site-packages\sqlalchemy\dialects\postgresql\asyncpg.py", line 572, in execute
    self._adapt_connection.await_(
  File "C:\Users\Admin\AppData\Roaming\Python\Python312\site-packages\sqlalchemy\util\_concurrency_py3k.py", line 132, in await_only
    return current.parent.switch(awaitable)  # type: ignore[no-any-return,attr-defined] # noqa: E501
           ^^^^^^^^^^^^^^^^^^^^^^^^^^^^^^^^
  File "C:\Users\Admin\AppData\Roaming\Python\Python312\site-packages\sqlalchemy\util\_concurrency_py3k.py", line 196, in greenlet_spawn
    value = await result
            ^^^^^^^^^^^^
  File "C:\Users\Admin\AppData\Roaming\Python\Python312\site-packages\sqlalchemy\dialects\postgresql\asyncpg.py", line 550, in _prepare_and_execute
    self._handle_exception(error)
  File "C:\Users\Admin\AppData\Roaming\Python\Python312\site-packages\sqlalchemy\dialects\postgresql\asyncpg.py", line 501, in _handle_exception
    self._adapt_connection._handle_exception(error)
  File "C:\Users\Admin\AppData\Roaming\Python\Python312\site-packages\sqlalchemy\dialects\postgresql\asyncpg.py", line 784, in _handle_exception
    raise translated_error from error
sqlalchemy.exc.ProgrammingError: (sqlalchemy.dialects.postgresql.asyncpg.ProgrammingError) <class 'asyncpg.exceptions.UndefinedTableError'>: relation "subcategories" does not exist
[SQL: SELECT subcategories.id, subcategories.category_id, subcategories.subcat_id, subcategories.name, subcategories.is_active, subcategories.created_on, subcategories.updated_on 
FROM subcategories 
WHERE subcategories.name IN ($1::VARCHAR, $2::VARCHAR)]
[parameters: ('Sample Subcategory 1', 'Sample Subcategory 2')]
(Background on this error at: https://sqlalche.me/e/20/f405)

During handling of the above exception, another exception occurred:

Traceback (most recent call last):
  File "D:\Projects\Fast_API\blog_app\backend\app\core\database.py", line 19, in get_db
    yield session
  File "C:\Users\Admin\AppData\Roaming\Python\Python312\site-packages\fastapi\routing.py", line 278, in app
    raw_response = await run_endpoint_function(
                   ^^^^^^^^^^^^^^^^^^^^^^^^^^^^
  File "C:\Users\Admin\AppData\Roaming\Python\Python312\site-packages\fastapi\routing.py", line 191, in run_endpoint_function
    return await dependant.call(**values)
           ^^^^^^^^^^^^^^^^^^^^^^^^^^^^^^
  File "D:\Projects\Fast_API\blog_app\backend\app\routers\subcategories.py", line 41, in create_subcategory_route
    raise HTTPException(
fastapi.exceptions.HTTPException: 500: Failed to create subcategory
ERROR 2024-09-23 20:14:29,802 root Failed to create subcategory: (sqlalchemy.dialects.postgresql.asyncpg.ProgrammingError) <class 'asyncpg.exceptions.UndefinedTableError'>: relation "subcategories" does not exist
[SQL: SELECT subcategories.id, subcategories.category_id, subcategories.subcat_id, subcategories.name, subcategories.is_active, subcategories.created_on, subcategories.updated_on 
FROM subcategories 
WHERE subcategories.name IN ($1::VARCHAR, $2::VARCHAR)]
[parameters: ('Sample Subcategory 1', 'Sample Subcategory 2')]
(Background on this error at: https://sqlalche.me/e/20/f405)
Traceback (most recent call last):
  File "C:\Users\Admin\AppData\Roaming\Python\Python312\site-packages\sqlalchemy\dialects\postgresql\asyncpg.py", line 514, in _prepare_and_execute
    prepared_stmt, attributes = await adapt_connection._prepare(
                                ^^^^^^^^^^^^^^^^^^^^^^^^^^^^^^^^
  File "C:\Users\Admin\AppData\Roaming\Python\Python312\site-packages\sqlalchemy\dialects\postgresql\asyncpg.py", line 760, in _prepare
    prepared_stmt = await self._connection.prepare(
                    ^^^^^^^^^^^^^^^^^^^^^^^^^^^^^^^
  File "C:\Users\Admin\AppData\Roaming\Python\Python312\site-packages\asyncpg\connection.py", line 636, in prepare
    return await self._prepare(
           ^^^^^^^^^^^^^^^^^^^^
  File "C:\Users\Admin\AppData\Roaming\Python\Python312\site-packages\asyncpg\connection.py", line 654, in _prepare
    stmt = await self._get_statement(
           ^^^^^^^^^^^^^^^^^^^^^^^^^^
  File "C:\Users\Admin\AppData\Roaming\Python\Python312\site-packages\asyncpg\connection.py", line 433, in _get_statement
    statement = await self._protocol.prepare(
                ^^^^^^^^^^^^^^^^^^^^^^^^^^^^^
  File "asyncpg\protocol\protocol.pyx", line 166, in prepare
asyncpg.exceptions.UndefinedTableError: relation "subcategories" does not exist

The above exception was the direct cause of the following exception:

Traceback (most recent call last):
  File "C:\Users\Admin\AppData\Roaming\Python\Python312\site-packages\sqlalchemy\engine\base.py", line 1967, in _exec_single_context
    self.dialect.do_execute(
  File "C:\Users\Admin\AppData\Roaming\Python\Python312\site-packages\sqlalchemy\engine\default.py", line 941, in do_execute
    cursor.execute(statement, parameters)
  File "C:\Users\Admin\AppData\Roaming\Python\Python312\site-packages\sqlalchemy\dialects\postgresql\asyncpg.py", line 572, in execute
    self._adapt_connection.await_(
  File "C:\Users\Admin\AppData\Roaming\Python\Python312\site-packages\sqlalchemy\util\_concurrency_py3k.py", line 132, in await_only
    return current.parent.switch(awaitable)  # type: ignore[no-any-return,attr-defined] # noqa: E501
           ^^^^^^^^^^^^^^^^^^^^^^^^^^^^^^^^
  File "C:\Users\Admin\AppData\Roaming\Python\Python312\site-packages\sqlalchemy\util\_concurrency_py3k.py", line 196, in greenlet_spawn
    value = await result
            ^^^^^^^^^^^^
  File "C:\Users\Admin\AppData\Roaming\Python\Python312\site-packages\sqlalchemy\dialects\postgresql\asyncpg.py", line 550, in _prepare_and_execute
    self._handle_exception(error)
  File "C:\Users\Admin\AppData\Roaming\Python\Python312\site-packages\sqlalchemy\dialects\postgresql\asyncpg.py", line 501, in _handle_exception
    self._adapt_connection._handle_exception(error)
  File "C:\Users\Admin\AppData\Roaming\Python\Python312\site-packages\sqlalchemy\dialects\postgresql\asyncpg.py", line 784, in _handle_exception
    raise translated_error from error
sqlalchemy.dialects.postgresql.asyncpg.AsyncAdapt_asyncpg_dbapi.ProgrammingError: <class 'asyncpg.exceptions.UndefinedTableError'>: relation "subcategories" does not exist

The above exception was the direct cause of the following exception:

Traceback (most recent call last):
  File "D:\Projects\Fast_API\blog_app\backend\app\routers\subcategories.py", line 24, in create_subcategory_route
    existing_subcategory = await db.execute(
                           ^^^^^^^^^^^^^^^^^
  File "C:\Users\Admin\AppData\Roaming\Python\Python312\site-packages\sqlalchemy\ext\asyncio\session.py", line 461, in execute
    result = await greenlet_spawn(
             ^^^^^^^^^^^^^^^^^^^^^
  File "C:\Users\Admin\AppData\Roaming\Python\Python312\site-packages\sqlalchemy\util\_concurrency_py3k.py", line 201, in greenlet_spawn
    result = context.throw(*sys.exc_info())
             ^^^^^^^^^^^^^^^^^^^^^^^^^^^^^^
  File "C:\Users\Admin\AppData\Roaming\Python\Python312\site-packages\sqlalchemy\orm\session.py", line 2362, in execute
    return self._execute_internal(
           ^^^^^^^^^^^^^^^^^^^^^^^
  File "C:\Users\Admin\AppData\Roaming\Python\Python312\site-packages\sqlalchemy\orm\session.py", line 2247, in _execute_internal
    result: Result[Any] = compile_state_cls.orm_execute_statement(
                          ^^^^^^^^^^^^^^^^^^^^^^^^^^^^^^^^^^^^^^^^
  File "C:\Users\Admin\AppData\Roaming\Python\Python312\site-packages\sqlalchemy\orm\context.py", line 305, in orm_execute_statement
    result = conn.execute(
             ^^^^^^^^^^^^^
  File "C:\Users\Admin\AppData\Roaming\Python\Python312\site-packages\sqlalchemy\engine\base.py", line 1418, in execute
    return meth(
           ^^^^^
  File "C:\Users\Admin\AppData\Roaming\Python\Python312\site-packages\sqlalchemy\sql\elements.py", line 515, in _execute_on_connection
    return connection._execute_clauseelement(
           ^^^^^^^^^^^^^^^^^^^^^^^^^^^^^^^^^^
  File "C:\Users\Admin\AppData\Roaming\Python\Python312\site-packages\sqlalchemy\engine\base.py", line 1640, in _execute_clauseelement
    ret = self._execute_context(
          ^^^^^^^^^^^^^^^^^^^^^^
  File "C:\Users\Admin\AppData\Roaming\Python\Python312\site-packages\sqlalchemy\engine\base.py", line 1846, in _execute_context
    return self._exec_single_context(
           ^^^^^^^^^^^^^^^^^^^^^^^^^^
  File "C:\Users\Admin\AppData\Roaming\Python\Python312\site-packages\sqlalchemy\engine\base.py", line 1986, in _exec_single_context
    self._handle_dbapi_exception(
  File "C:\Users\Admin\AppData\Roaming\Python\Python312\site-packages\sqlalchemy\engine\base.py", line 2355, in _handle_dbapi_exception
    raise sqlalchemy_exception.with_traceback(exc_info[2]) from e
  File "C:\Users\Admin\AppData\Roaming\Python\Python312\site-packages\sqlalchemy\engine\base.py", line 1967, in _exec_single_context
    self.dialect.do_execute(
  File "C:\Users\Admin\AppData\Roaming\Python\Python312\site-packages\sqlalchemy\engine\default.py", line 941, in do_execute
    cursor.execute(statement, parameters)
  File "C:\Users\Admin\AppData\Roaming\Python\Python312\site-packages\sqlalchemy\dialects\postgresql\asyncpg.py", line 572, in execute
    self._adapt_connection.await_(
  File "C:\Users\Admin\AppData\Roaming\Python\Python312\site-packages\sqlalchemy\util\_concurrency_py3k.py", line 132, in await_only
    return current.parent.switch(awaitable)  # type: ignore[no-any-return,attr-defined] # noqa: E501
           ^^^^^^^^^^^^^^^^^^^^^^^^^^^^^^^^
  File "C:\Users\Admin\AppData\Roaming\Python\Python312\site-packages\sqlalchemy\util\_concurrency_py3k.py", line 196, in greenlet_spawn
    value = await result
            ^^^^^^^^^^^^
  File "C:\Users\Admin\AppData\Roaming\Python\Python312\site-packages\sqlalchemy\dialects\postgresql\asyncpg.py", line 550, in _prepare_and_execute
    self._handle_exception(error)
  File "C:\Users\Admin\AppData\Roaming\Python\Python312\site-packages\sqlalchemy\dialects\postgresql\asyncpg.py", line 501, in _handle_exception
    self._adapt_connection._handle_exception(error)
  File "C:\Users\Admin\AppData\Roaming\Python\Python312\site-packages\sqlalchemy\dialects\postgresql\asyncpg.py", line 784, in _handle_exception
    raise translated_error from error
sqlalchemy.exc.ProgrammingError: (sqlalchemy.dialects.postgresql.asyncpg.ProgrammingError) <class 'asyncpg.exceptions.UndefinedTableError'>: relation "subcategories" does not exist
[SQL: SELECT subcategories.id, subcategories.category_id, subcategories.subcat_id, subcategories.name, subcategories.is_active, subcategories.created_on, subcategories.updated_on 
FROM subcategories 
WHERE subcategories.name IN ($1::VARCHAR, $2::VARCHAR)]
[parameters: ('Sample Subcategory 1', 'Sample Subcategory 2')]
(Background on this error at: https://sqlalche.me/e/20/f405)
ERROR 2024-09-23 20:14:29,838 root Unexpected error: 500: Failed to create subcategory
Traceback (most recent call last):
  File "C:\Users\Admin\AppData\Roaming\Python\Python312\site-packages\sqlalchemy\dialects\postgresql\asyncpg.py", line 514, in _prepare_and_execute
    prepared_stmt, attributes = await adapt_connection._prepare(
                                ^^^^^^^^^^^^^^^^^^^^^^^^^^^^^^^^
  File "C:\Users\Admin\AppData\Roaming\Python\Python312\site-packages\sqlalchemy\dialects\postgresql\asyncpg.py", line 760, in _prepare
    prepared_stmt = await self._connection.prepare(
                    ^^^^^^^^^^^^^^^^^^^^^^^^^^^^^^^
  File "C:\Users\Admin\AppData\Roaming\Python\Python312\site-packages\asyncpg\connection.py", line 636, in prepare
    return await self._prepare(
           ^^^^^^^^^^^^^^^^^^^^
  File "C:\Users\Admin\AppData\Roaming\Python\Python312\site-packages\asyncpg\connection.py", line 654, in _prepare
    stmt = await self._get_statement(
           ^^^^^^^^^^^^^^^^^^^^^^^^^^
  File "C:\Users\Admin\AppData\Roaming\Python\Python312\site-packages\asyncpg\connection.py", line 433, in _get_statement
    statement = await self._protocol.prepare(
                ^^^^^^^^^^^^^^^^^^^^^^^^^^^^^
  File "asyncpg\protocol\protocol.pyx", line 166, in prepare
asyncpg.exceptions.UndefinedTableError: relation "subcategories" does not exist

The above exception was the direct cause of the following exception:

Traceback (most recent call last):
  File "C:\Users\Admin\AppData\Roaming\Python\Python312\site-packages\sqlalchemy\engine\base.py", line 1967, in _exec_single_context
    self.dialect.do_execute(
  File "C:\Users\Admin\AppData\Roaming\Python\Python312\site-packages\sqlalchemy\engine\default.py", line 941, in do_execute
    cursor.execute(statement, parameters)
  File "C:\Users\Admin\AppData\Roaming\Python\Python312\site-packages\sqlalchemy\dialects\postgresql\asyncpg.py", line 572, in execute
    self._adapt_connection.await_(
  File "C:\Users\Admin\AppData\Roaming\Python\Python312\site-packages\sqlalchemy\util\_concurrency_py3k.py", line 132, in await_only
    return current.parent.switch(awaitable)  # type: ignore[no-any-return,attr-defined] # noqa: E501
           ^^^^^^^^^^^^^^^^^^^^^^^^^^^^^^^^
  File "C:\Users\Admin\AppData\Roaming\Python\Python312\site-packages\sqlalchemy\util\_concurrency_py3k.py", line 196, in greenlet_spawn
    value = await result
            ^^^^^^^^^^^^
  File "C:\Users\Admin\AppData\Roaming\Python\Python312\site-packages\sqlalchemy\dialects\postgresql\asyncpg.py", line 550, in _prepare_and_execute
    self._handle_exception(error)
  File "C:\Users\Admin\AppData\Roaming\Python\Python312\site-packages\sqlalchemy\dialects\postgresql\asyncpg.py", line 501, in _handle_exception
    self._adapt_connection._handle_exception(error)
  File "C:\Users\Admin\AppData\Roaming\Python\Python312\site-packages\sqlalchemy\dialects\postgresql\asyncpg.py", line 784, in _handle_exception
    raise translated_error from error
sqlalchemy.dialects.postgresql.asyncpg.AsyncAdapt_asyncpg_dbapi.ProgrammingError: <class 'asyncpg.exceptions.UndefinedTableError'>: relation "subcategories" does not exist

The above exception was the direct cause of the following exception:

Traceback (most recent call last):
  File "D:\Projects\Fast_API\blog_app\backend\app\routers\subcategories.py", line 24, in create_subcategory_route
    existing_subcategory = await db.execute(
                           ^^^^^^^^^^^^^^^^^
  File "C:\Users\Admin\AppData\Roaming\Python\Python312\site-packages\sqlalchemy\ext\asyncio\session.py", line 461, in execute
    result = await greenlet_spawn(
             ^^^^^^^^^^^^^^^^^^^^^
  File "C:\Users\Admin\AppData\Roaming\Python\Python312\site-packages\sqlalchemy\util\_concurrency_py3k.py", line 201, in greenlet_spawn
    result = context.throw(*sys.exc_info())
             ^^^^^^^^^^^^^^^^^^^^^^^^^^^^^^
  File "C:\Users\Admin\AppData\Roaming\Python\Python312\site-packages\sqlalchemy\orm\session.py", line 2362, in execute
    return self._execute_internal(
           ^^^^^^^^^^^^^^^^^^^^^^^
  File "C:\Users\Admin\AppData\Roaming\Python\Python312\site-packages\sqlalchemy\orm\session.py", line 2247, in _execute_internal
    result: Result[Any] = compile_state_cls.orm_execute_statement(
                          ^^^^^^^^^^^^^^^^^^^^^^^^^^^^^^^^^^^^^^^^
  File "C:\Users\Admin\AppData\Roaming\Python\Python312\site-packages\sqlalchemy\orm\context.py", line 305, in orm_execute_statement
    result = conn.execute(
             ^^^^^^^^^^^^^
  File "C:\Users\Admin\AppData\Roaming\Python\Python312\site-packages\sqlalchemy\engine\base.py", line 1418, in execute
    return meth(
           ^^^^^
  File "C:\Users\Admin\AppData\Roaming\Python\Python312\site-packages\sqlalchemy\sql\elements.py", line 515, in _execute_on_connection
    return connection._execute_clauseelement(
           ^^^^^^^^^^^^^^^^^^^^^^^^^^^^^^^^^^
  File "C:\Users\Admin\AppData\Roaming\Python\Python312\site-packages\sqlalchemy\engine\base.py", line 1640, in _execute_clauseelement
    ret = self._execute_context(
          ^^^^^^^^^^^^^^^^^^^^^^
  File "C:\Users\Admin\AppData\Roaming\Python\Python312\site-packages\sqlalchemy\engine\base.py", line 1846, in _execute_context
    return self._exec_single_context(
           ^^^^^^^^^^^^^^^^^^^^^^^^^^
  File "C:\Users\Admin\AppData\Roaming\Python\Python312\site-packages\sqlalchemy\engine\base.py", line 1986, in _exec_single_context
    self._handle_dbapi_exception(
  File "C:\Users\Admin\AppData\Roaming\Python\Python312\site-packages\sqlalchemy\engine\base.py", line 2355, in _handle_dbapi_exception
    raise sqlalchemy_exception.with_traceback(exc_info[2]) from e
  File "C:\Users\Admin\AppData\Roaming\Python\Python312\site-packages\sqlalchemy\engine\base.py", line 1967, in _exec_single_context
    self.dialect.do_execute(
  File "C:\Users\Admin\AppData\Roaming\Python\Python312\site-packages\sqlalchemy\engine\default.py", line 941, in do_execute
    cursor.execute(statement, parameters)
  File "C:\Users\Admin\AppData\Roaming\Python\Python312\site-packages\sqlalchemy\dialects\postgresql\asyncpg.py", line 572, in execute
    self._adapt_connection.await_(
  File "C:\Users\Admin\AppData\Roaming\Python\Python312\site-packages\sqlalchemy\util\_concurrency_py3k.py", line 132, in await_only
    return current.parent.switch(awaitable)  # type: ignore[no-any-return,attr-defined] # noqa: E501
           ^^^^^^^^^^^^^^^^^^^^^^^^^^^^^^^^
  File "C:\Users\Admin\AppData\Roaming\Python\Python312\site-packages\sqlalchemy\util\_concurrency_py3k.py", line 196, in greenlet_spawn
    value = await result
            ^^^^^^^^^^^^
  File "C:\Users\Admin\AppData\Roaming\Python\Python312\site-packages\sqlalchemy\dialects\postgresql\asyncpg.py", line 550, in _prepare_and_execute
    self._handle_exception(error)
  File "C:\Users\Admin\AppData\Roaming\Python\Python312\site-packages\sqlalchemy\dialects\postgresql\asyncpg.py", line 501, in _handle_exception
    self._adapt_connection._handle_exception(error)
  File "C:\Users\Admin\AppData\Roaming\Python\Python312\site-packages\sqlalchemy\dialects\postgresql\asyncpg.py", line 784, in _handle_exception
    raise translated_error from error
sqlalchemy.exc.ProgrammingError: (sqlalchemy.dialects.postgresql.asyncpg.ProgrammingError) <class 'asyncpg.exceptions.UndefinedTableError'>: relation "subcategories" does not exist
[SQL: SELECT subcategories.id, subcategories.category_id, subcategories.subcat_id, subcategories.name, subcategories.is_active, subcategories.created_on, subcategories.updated_on 
FROM subcategories 
WHERE subcategories.name IN ($1::VARCHAR, $2::VARCHAR)]
[parameters: ('Sample Subcategory 1', 'Sample Subcategory 2')]
(Background on this error at: https://sqlalche.me/e/20/f405)

During handling of the above exception, another exception occurred:

Traceback (most recent call last):
  File "D:\Projects\Fast_API\blog_app\backend\app\core\database.py", line 19, in get_db
    yield session
  File "C:\Users\Admin\AppData\Roaming\Python\Python312\site-packages\fastapi\routing.py", line 278, in app
    raw_response = await run_endpoint_function(
                   ^^^^^^^^^^^^^^^^^^^^^^^^^^^^
  File "C:\Users\Admin\AppData\Roaming\Python\Python312\site-packages\fastapi\routing.py", line 191, in run_endpoint_function
    return await dependant.call(**values)
           ^^^^^^^^^^^^^^^^^^^^^^^^^^^^^^
  File "D:\Projects\Fast_API\blog_app\backend\app\routers\subcategories.py", line 41, in create_subcategory_route
    raise HTTPException(
fastapi.exceptions.HTTPException: 500: Failed to create subcategory
ERROR 2024-09-23 21:12:59 root Unexpected error: Unable to serialize unknown type: <class 'app.models.subcategories.Subcategory'>
Traceback (most recent call last):
  File "D:\Projects\Fast_API\blog_app\backend\app\core\database.py", line 21, in get_db
    yield session
  File "C:\Users\Admin\AppData\Roaming\Python\Python312\site-packages\fastapi\routing.py", line 296, in app
    content = await serialize_response(
              ^^^^^^^^^^^^^^^^^^^^^^^^^
  File "C:\Users\Admin\AppData\Roaming\Python\Python312\site-packages\fastapi\routing.py", line 160, in serialize_response
    return field.serialize(
           ^^^^^^^^^^^^^^^^
  File "C:\Users\Admin\AppData\Roaming\Python\Python312\site-packages\fastapi\_compat.py", line 149, in serialize
    return self._type_adapter.dump_python(
           ^^^^^^^^^^^^^^^^^^^^^^^^^^^^^^^
  File "C:\Users\Admin\AppData\Roaming\Python\Python312\site-packages\pydantic\type_adapter.py", line 142, in wrapped
    return func(self, *args, **kwargs)
           ^^^^^^^^^^^^^^^^^^^^^^^^^^^
  File "C:\Users\Admin\AppData\Roaming\Python\Python312\site-packages\pydantic\type_adapter.py", line 458, in dump_python
    return self.serializer.to_python(
           ^^^^^^^^^^^^^^^^^^^^^^^^^^
pydantic_core._pydantic_core.PydanticSerializationError: Unable to serialize unknown type: <class 'app.models.subcategories.Subcategory'>
ERROR 2024-09-23 21:25:01 root HTTP error: Subcategory Name already exists
ERROR 2024-09-23 21:25:01 root Unexpected error: 400: Subcategory Name already exists
Traceback (most recent call last):
  File "D:\Projects\Fast_API\blog_app\backend\app\core\database.py", line 21, in get_db
    yield session
  File "C:\Users\Admin\AppData\Roaming\Python\Python312\site-packages\fastapi\routing.py", line 278, in app
    raw_response = await run_endpoint_function(
                   ^^^^^^^^^^^^^^^^^^^^^^^^^^^^
  File "C:\Users\Admin\AppData\Roaming\Python\Python312\site-packages\fastapi\routing.py", line 191, in run_endpoint_function
    return await dependant.call(**values)
           ^^^^^^^^^^^^^^^^^^^^^^^^^^^^^^
  File "D:\Projects\Fast_API\blog_app\backend\app\routers\subcategories.py", line 37, in create_subcategory_route
    raise he
  File "D:\Projects\Fast_API\blog_app\backend\app\routers\subcategories.py", line 28, in create_subcategory_route
    raise HTTPException(status_code=400, detail="Subcategory Name already exists")
fastapi.exceptions.HTTPException: 400: Subcategory Name already exists
ERROR 2024-09-23 21:33:39 root HTTP error: Subcategory name already exists
ERROR 2024-09-23 21:33:39 root Unexpected error: 400: Subcategory name already exists
Traceback (most recent call last):
  File "D:\Projects\Fast_API\blog_app\backend\app\core\database.py", line 21, in get_db
    yield session
  File "C:\Users\Admin\AppData\Roaming\Python\Python312\site-packages\fastapi\routing.py", line 278, in app
    raw_response = await run_endpoint_function(
                   ^^^^^^^^^^^^^^^^^^^^^^^^^^^^
  File "C:\Users\Admin\AppData\Roaming\Python\Python312\site-packages\fastapi\routing.py", line 191, in run_endpoint_function
    return await dependant.call(**values)
           ^^^^^^^^^^^^^^^^^^^^^^^^^^^^^^
  File "D:\Projects\Fast_API\blog_app\backend\app\routers\subcategories.py", line 43, in create_subcategory_route
    raise he
  File "D:\Projects\Fast_API\blog_app\backend\app\routers\subcategories.py", line 29, in create_subcategory_route
    raise HTTPException(
fastapi.exceptions.HTTPException: 400: Subcategory name already exists
ERROR 2024-09-23 21:35:53 root HTTP error: Subcategory name already exists
ERROR 2024-09-23 21:35:53 root Unexpected error: 400: Subcategory name already exists
Traceback (most recent call last):
  File "D:\Projects\Fast_API\blog_app\backend\app\core\database.py", line 21, in get_db
    yield session
  File "C:\Users\Admin\AppData\Roaming\Python\Python312\site-packages\fastapi\routing.py", line 278, in app
    raw_response = await run_endpoint_function(
                   ^^^^^^^^^^^^^^^^^^^^^^^^^^^^
  File "C:\Users\Admin\AppData\Roaming\Python\Python312\site-packages\fastapi\routing.py", line 191, in run_endpoint_function
    return await dependant.call(**values)
           ^^^^^^^^^^^^^^^^^^^^^^^^^^^^^^
  File "D:\Projects\Fast_API\blog_app\backend\app\routers\subcategories.py", line 43, in create_subcategory_route
    raise he
  File "D:\Projects\Fast_API\blog_app\backend\app\routers\subcategories.py", line 29, in create_subcategory_route
    raise HTTPException(
fastapi.exceptions.HTTPException: 400: Subcategory name already exists
ERROR 2024-09-23 21:49:04 root HTTP error: Subcategory names already exist: Sample Subcategory 3, Sample Subcategory 4, Sample Subcategory 5, Sample Subcategory 6
ERROR 2024-09-23 21:49:04 root Unexpected error: 400: Subcategory names already exist: Sample Subcategory 3, Sample Subcategory 4, Sample Subcategory 5, Sample Subcategory 6
Traceback (most recent call last):
  File "D:\Projects\Fast_API\blog_app\backend\app\core\database.py", line 21, in get_db
    yield session
  File "C:\Users\Admin\AppData\Roaming\Python\Python312\site-packages\fastapi\routing.py", line 278, in app
    raw_response = await run_endpoint_function(
                   ^^^^^^^^^^^^^^^^^^^^^^^^^^^^
  File "C:\Users\Admin\AppData\Roaming\Python\Python312\site-packages\fastapi\routing.py", line 191, in run_endpoint_function
    return await dependant.call(**values)
           ^^^^^^^^^^^^^^^^^^^^^^^^^^^^^^
  File "D:\Projects\Fast_API\blog_app\backend\app\routers\subcategories.py", line 41, in create_subcategory_route
    raise he
  File "D:\Projects\Fast_API\blog_app\backend\app\routers\subcategories.py", line 27, in create_subcategory_route
    raise HTTPException(
fastapi.exceptions.HTTPException: 400: Subcategory names already exist: Sample Subcategory 3, Sample Subcategory 4, Sample Subcategory 5, Sample Subcategory 6
ERROR 2024-09-23 21:58:18 root Unexpected error: Unable to serialize unknown type: <class 'app.models.subcategories.Subcategory'>
Traceback (most recent call last):
  File "D:\Projects\Fast_API\blog_app\backend\app\core\database.py", line 21, in get_db
    yield session
  File "C:\Users\Admin\AppData\Roaming\Python\Python312\site-packages\fastapi\routing.py", line 296, in app
    content = await serialize_response(
              ^^^^^^^^^^^^^^^^^^^^^^^^^
  File "C:\Users\Admin\AppData\Roaming\Python\Python312\site-packages\fastapi\routing.py", line 160, in serialize_response
    return field.serialize(
           ^^^^^^^^^^^^^^^^
  File "C:\Users\Admin\AppData\Roaming\Python\Python312\site-packages\fastapi\_compat.py", line 149, in serialize
    return self._type_adapter.dump_python(
           ^^^^^^^^^^^^^^^^^^^^^^^^^^^^^^^
  File "C:\Users\Admin\AppData\Roaming\Python\Python312\site-packages\pydantic\type_adapter.py", line 142, in wrapped
    return func(self, *args, **kwargs)
           ^^^^^^^^^^^^^^^^^^^^^^^^^^^
  File "C:\Users\Admin\AppData\Roaming\Python\Python312\site-packages\pydantic\type_adapter.py", line 458, in dump_python
    return self.serializer.to_python(
           ^^^^^^^^^^^^^^^^^^^^^^^^^^
pydantic_core._pydantic_core.PydanticSerializationError: Unable to serialize unknown type: <class 'app.models.subcategories.Subcategory'>
ERROR 2024-09-23 22:31:40 root Failed to fetch subcategories: 'method' object is not iterable
ERROR 2024-09-23 22:31:40 root Unexpected error: 500: Failed to fetch subcategories
Traceback (most recent call last):
  File "D:\Projects\Fast_API\blog_app\backend\app\routers\subcategories.py", line 55, in get_subcategories_route
    "data": [SubcategoryModel.from_orm(subcat) for subcat in subcategories]
            ^^^^^^^^^^^^^^^^^^^^^^^^^^^^^^^^^^^^^^^^^^^^^^^^^^^^^^^^^^^^^^^
TypeError: 'method' object is not iterable

During handling of the above exception, another exception occurred:

Traceback (most recent call last):
  File "D:\Projects\Fast_API\blog_app\backend\app\core\database.py", line 21, in get_db
    yield session
  File "C:\Users\Admin\AppData\Roaming\Python\Python312\site-packages\fastapi\routing.py", line 278, in app
    raw_response = await run_endpoint_function(
                   ^^^^^^^^^^^^^^^^^^^^^^^^^^^^
  File "C:\Users\Admin\AppData\Roaming\Python\Python312\site-packages\fastapi\routing.py", line 191, in run_endpoint_function
    return await dependant.call(**values)
           ^^^^^^^^^^^^^^^^^^^^^^^^^^^^^^
  File "D:\Projects\Fast_API\blog_app\backend\app\routers\subcategories.py", line 60, in get_subcategories_route
    raise HTTPException(
fastapi.exceptions.HTTPException: 500: Failed to fetch subcategories
ERROR 2024-09-23 22:46:31 root Failed to fetch subcategories: 1 validation error for SubcategoryModel
  Input should be a valid dictionary or object to extract fields from [type=model_attributes_type, input_value=[<Subcategory Sample Subc...-09-23 21:35:35.332145>], input_type=list]
    For further information visit https://errors.pydantic.dev/2.8/v/model_attributes_type
ERROR 2024-09-23 22:46:31 root Unexpected error: 500: Failed to fetch subcategories
Traceback (most recent call last):
  File "D:\Projects\Fast_API\blog_app\backend\app\routers\subcategories.py", line 60, in get_subcategories_route
    "data": [SubcategoryModel.from_orm(subcat) for subcat in subcategories]
             ^^^^^^^^^^^^^^^^^^^^^^^^^^^^^^^^^
  File "C:\Users\Admin\AppData\Roaming\Python\Python312\site-packages\pydantic\main.py", line 1237, in from_orm
    return cls.model_validate(obj)
           ^^^^^^^^^^^^^^^^^^^^^^^
  File "C:\Users\Admin\AppData\Roaming\Python\Python312\site-packages\pydantic\main.py", line 568, in model_validate
    return cls.__pydantic_validator__.validate_python(
           ^^^^^^^^^^^^^^^^^^^^^^^^^^^^^^^^^^^^^^^^^^^
pydantic_core._pydantic_core.ValidationError: 1 validation error for SubcategoryModel
  Input should be a valid dictionary or object to extract fields from [type=model_attributes_type, input_value=[<Subcategory Sample Subc...-09-23 21:35:35.332145>], input_type=list]
    For further information visit https://errors.pydantic.dev/2.8/v/model_attributes_type

During handling of the above exception, another exception occurred:

Traceback (most recent call last):
  File "D:\Projects\Fast_API\blog_app\backend\app\core\database.py", line 21, in get_db
    yield session
  File "C:\Users\Admin\AppData\Roaming\Python\Python312\site-packages\fastapi\routing.py", line 278, in app
    raw_response = await run_endpoint_function(
                   ^^^^^^^^^^^^^^^^^^^^^^^^^^^^
  File "C:\Users\Admin\AppData\Roaming\Python\Python312\site-packages\fastapi\routing.py", line 191, in run_endpoint_function
    return await dependant.call(**values)
           ^^^^^^^^^^^^^^^^^^^^^^^^^^^^^^
  File "D:\Projects\Fast_API\blog_app\backend\app\routers\subcategories.py", line 65, in get_subcategories_route
    raise HTTPException(
fastapi.exceptions.HTTPException: 500: Failed to fetch subcategories
ERROR 2024-09-23 22:50:41 root Unexpected error: Unable to serialize unknown type: <class 'app.models.subcategories.Subcategory'>
Traceback (most recent call last):
  File "D:\Projects\Fast_API\blog_app\backend\app\core\database.py", line 21, in get_db
    yield session
  File "C:\Users\Admin\AppData\Roaming\Python\Python312\site-packages\fastapi\routing.py", line 296, in app
    content = await serialize_response(
              ^^^^^^^^^^^^^^^^^^^^^^^^^
  File "C:\Users\Admin\AppData\Roaming\Python\Python312\site-packages\fastapi\routing.py", line 160, in serialize_response
    return field.serialize(
           ^^^^^^^^^^^^^^^^
  File "C:\Users\Admin\AppData\Roaming\Python\Python312\site-packages\fastapi\_compat.py", line 149, in serialize
    return self._type_adapter.dump_python(
           ^^^^^^^^^^^^^^^^^^^^^^^^^^^^^^^
  File "C:\Users\Admin\AppData\Roaming\Python\Python312\site-packages\pydantic\type_adapter.py", line 142, in wrapped
    return func(self, *args, **kwargs)
           ^^^^^^^^^^^^^^^^^^^^^^^^^^^
  File "C:\Users\Admin\AppData\Roaming\Python\Python312\site-packages\pydantic\type_adapter.py", line 458, in dump_python
    return self.serializer.to_python(
           ^^^^^^^^^^^^^^^^^^^^^^^^^^
pydantic_core._pydantic_core.PydanticSerializationError: Unable to serialize unknown type: <class 'app.models.subcategories.Subcategory'>
ERROR 2024-09-23 23:02:13 root Failed to update subcategory: name 'get_subcategory' is not defined
Traceback (most recent call last):
  File "D:\Projects\Fast_API\blog_app\backend\app\routers\subcategories.py", line 96, in update_subcategory_route
    updated_subcategory = await update_subcategory(db, subcategory_id, subcategory_data)
                          ^^^^^^^^^^^^^^^^^^^^^^^^^^^^^^^^^^^^^^^^^^^^^^^^^^^^^^^^^^^^^^
  File "D:\Projects\Fast_API\blog_app\backend\app\services\subcategories.py", line 60, in update_subcategory
    subcategory = await get_subcategory(db, subcategory_id)
                        ^^^^^^^^^^^^^^^
NameError: name 'get_subcategory' is not defined. Did you mean: 'create_subcategory'?
ERROR 2024-09-23 23:02:13 root Unexpected error: 500: Failed to update subcategory
Traceback (most recent call last):
  File "D:\Projects\Fast_API\blog_app\backend\app\routers\subcategories.py", line 96, in update_subcategory_route
    updated_subcategory = await update_subcategory(db, subcategory_id, subcategory_data)
                          ^^^^^^^^^^^^^^^^^^^^^^^^^^^^^^^^^^^^^^^^^^^^^^^^^^^^^^^^^^^^^^
  File "D:\Projects\Fast_API\blog_app\backend\app\services\subcategories.py", line 60, in update_subcategory
    subcategory = await get_subcategory(db, subcategory_id)
                        ^^^^^^^^^^^^^^^
NameError: name 'get_subcategory' is not defined. Did you mean: 'create_subcategory'?

During handling of the above exception, another exception occurred:

Traceback (most recent call last):
  File "D:\Projects\Fast_API\blog_app\backend\app\core\database.py", line 21, in get_db
    yield session
  File "C:\Users\Admin\AppData\Roaming\Python\Python312\site-packages\fastapi\routing.py", line 278, in app
    raw_response = await run_endpoint_function(
                   ^^^^^^^^^^^^^^^^^^^^^^^^^^^^
  File "C:\Users\Admin\AppData\Roaming\Python\Python312\site-packages\fastapi\routing.py", line 191, in run_endpoint_function
    return await dependant.call(**values)
           ^^^^^^^^^^^^^^^^^^^^^^^^^^^^^^
  File "D:\Projects\Fast_API\blog_app\backend\app\routers\subcategories.py", line 108, in update_subcategory_route
    raise HTTPException(
fastapi.exceptions.HTTPException: 500: Failed to update subcategory
ERROR 2024-09-23 23:04:14 root Failed to update subcategory: name 'get_subcategory' is not defined
Traceback (most recent call last):
  File "D:\Projects\Fast_API\blog_app\backend\app\routers\subcategories.py", line 95, in update_subcategory_route
    updated_subcategory = await update_subcategory(db, subcategory_id, subcategory_data)
                          ^^^^^^^^^^^^^^^^^^^^^^^^^^^^^^^^^^^^^^^^^^^^^^^^^^^^^^^^^^^^^^
  File "D:\Projects\Fast_API\blog_app\backend\app\services\subcategories.py", line 60, in update_subcategory
    subcategory = await get_subcategory(db, subcategory_id)
                        ^^^^^^^^^^^^^^^
NameError: name 'get_subcategory' is not defined. Did you mean: 'create_subcategory'?
ERROR 2024-09-23 23:04:14 root Unexpected error: 500: Failed to update subcategory
Traceback (most recent call last):
  File "D:\Projects\Fast_API\blog_app\backend\app\routers\subcategories.py", line 95, in update_subcategory_route
    updated_subcategory = await update_subcategory(db, subcategory_id, subcategory_data)
                          ^^^^^^^^^^^^^^^^^^^^^^^^^^^^^^^^^^^^^^^^^^^^^^^^^^^^^^^^^^^^^^
  File "D:\Projects\Fast_API\blog_app\backend\app\services\subcategories.py", line 60, in update_subcategory
    subcategory = await get_subcategory(db, subcategory_id)
                        ^^^^^^^^^^^^^^^
NameError: name 'get_subcategory' is not defined. Did you mean: 'create_subcategory'?

During handling of the above exception, another exception occurred:

Traceback (most recent call last):
  File "D:\Projects\Fast_API\blog_app\backend\app\core\database.py", line 21, in get_db
    yield session
  File "C:\Users\Admin\AppData\Roaming\Python\Python312\site-packages\fastapi\routing.py", line 278, in app
    raw_response = await run_endpoint_function(
                   ^^^^^^^^^^^^^^^^^^^^^^^^^^^^
  File "C:\Users\Admin\AppData\Roaming\Python\Python312\site-packages\fastapi\routing.py", line 191, in run_endpoint_function
    return await dependant.call(**values)
           ^^^^^^^^^^^^^^^^^^^^^^^^^^^^^^
  File "D:\Projects\Fast_API\blog_app\backend\app\routers\subcategories.py", line 111, in update_subcategory_route
    raise HTTPException(
fastapi.exceptions.HTTPException: 500: Failed to update subcategory
ERROR 2024-09-23 23:04:54 root Unexpected error: Unable to serialize unknown type: <class 'app.models.subcategories.Subcategory'>
Traceback (most recent call last):
  File "D:\Projects\Fast_API\blog_app\backend\app\core\database.py", line 21, in get_db
    yield session
  File "C:\Users\Admin\AppData\Roaming\Python\Python312\site-packages\fastapi\routing.py", line 296, in app
    content = await serialize_response(
              ^^^^^^^^^^^^^^^^^^^^^^^^^
  File "C:\Users\Admin\AppData\Roaming\Python\Python312\site-packages\fastapi\routing.py", line 160, in serialize_response
    return field.serialize(
           ^^^^^^^^^^^^^^^^
  File "C:\Users\Admin\AppData\Roaming\Python\Python312\site-packages\fastapi\_compat.py", line 149, in serialize
    return self._type_adapter.dump_python(
           ^^^^^^^^^^^^^^^^^^^^^^^^^^^^^^^
  File "C:\Users\Admin\AppData\Roaming\Python\Python312\site-packages\pydantic\type_adapter.py", line 142, in wrapped
    return func(self, *args, **kwargs)
           ^^^^^^^^^^^^^^^^^^^^^^^^^^^
  File "C:\Users\Admin\AppData\Roaming\Python\Python312\site-packages\pydantic\type_adapter.py", line 458, in dump_python
    return self.serializer.to_python(
           ^^^^^^^^^^^^^^^^^^^^^^^^^^
pydantic_core._pydantic_core.PydanticSerializationError: Unable to serialize unknown type: <class 'app.models.subcategories.Subcategory'>
ERROR 2024-09-23 23:05:42 root Failed to update subcategory: name 'get_subcategory' is not defined
Traceback (most recent call last):
  File "D:\Projects\Fast_API\blog_app\backend\app\routers\subcategories.py", line 95, in update_subcategory_route
    updated_subcategory = await update_subcategory(db, subcategory_id, subcategory_data)
                          ^^^^^^^^^^^^^^^^^^^^^^^^^^^^^^^^^^^^^^^^^^^^^^^^^^^^^^^^^^^^^^
  File "D:\Projects\Fast_API\blog_app\backend\app\services\subcategories.py", line 60, in update_subcategory
    subcategory = await get_subcategory(db, subcategory_id)
                        ^^^^^^^^^^^^^^^
NameError: name 'get_subcategory' is not defined. Did you mean: 'create_subcategory'?
ERROR 2024-09-23 23:05:42 root Unexpected error: 500: Failed to update subcategory
Traceback (most recent call last):
  File "D:\Projects\Fast_API\blog_app\backend\app\routers\subcategories.py", line 95, in update_subcategory_route
    updated_subcategory = await update_subcategory(db, subcategory_id, subcategory_data)
                          ^^^^^^^^^^^^^^^^^^^^^^^^^^^^^^^^^^^^^^^^^^^^^^^^^^^^^^^^^^^^^^
  File "D:\Projects\Fast_API\blog_app\backend\app\services\subcategories.py", line 60, in update_subcategory
    subcategory = await get_subcategory(db, subcategory_id)
                        ^^^^^^^^^^^^^^^
NameError: name 'get_subcategory' is not defined. Did you mean: 'create_subcategory'?

During handling of the above exception, another exception occurred:

Traceback (most recent call last):
  File "D:\Projects\Fast_API\blog_app\backend\app\core\database.py", line 21, in get_db
    yield session
  File "C:\Users\Admin\AppData\Roaming\Python\Python312\site-packages\fastapi\routing.py", line 278, in app
    raw_response = await run_endpoint_function(
                   ^^^^^^^^^^^^^^^^^^^^^^^^^^^^
  File "C:\Users\Admin\AppData\Roaming\Python\Python312\site-packages\fastapi\routing.py", line 191, in run_endpoint_function
    return await dependant.call(**values)
           ^^^^^^^^^^^^^^^^^^^^^^^^^^^^^^
  File "D:\Projects\Fast_API\blog_app\backend\app\routers\subcategories.py", line 111, in update_subcategory_route
    raise HTTPException(
fastapi.exceptions.HTTPException: 500: Failed to update subcategory
ERROR 2024-09-23 23:09:23 root Unexpected error: Unable to serialize unknown type: <class 'app.models.subcategories.Subcategory'>
Traceback (most recent call last):
  File "D:\Projects\Fast_API\blog_app\backend\app\core\database.py", line 21, in get_db
    yield session
  File "C:\Users\Admin\AppData\Roaming\Python\Python312\site-packages\fastapi\routing.py", line 296, in app
    content = await serialize_response(
              ^^^^^^^^^^^^^^^^^^^^^^^^^
  File "C:\Users\Admin\AppData\Roaming\Python\Python312\site-packages\fastapi\routing.py", line 160, in serialize_response
    return field.serialize(
           ^^^^^^^^^^^^^^^^
  File "C:\Users\Admin\AppData\Roaming\Python\Python312\site-packages\fastapi\_compat.py", line 149, in serialize
    return self._type_adapter.dump_python(
           ^^^^^^^^^^^^^^^^^^^^^^^^^^^^^^^
  File "C:\Users\Admin\AppData\Roaming\Python\Python312\site-packages\pydantic\type_adapter.py", line 142, in wrapped
    return func(self, *args, **kwargs)
           ^^^^^^^^^^^^^^^^^^^^^^^^^^^
  File "C:\Users\Admin\AppData\Roaming\Python\Python312\site-packages\pydantic\type_adapter.py", line 458, in dump_python
    return self.serializer.to_python(
           ^^^^^^^^^^^^^^^^^^^^^^^^^^
pydantic_core._pydantic_core.PydanticSerializationError: Unable to serialize unknown type: <class 'app.models.subcategories.Subcategory'>
ERROR 2024-09-23 23:36:03 root HTTP error: Subcategory names already exist: New Sample Subcategory
ERROR 2024-09-23 23:36:03 root Unexpected error: 400: Subcategory names already exist: New Sample Subcategory
Traceback (most recent call last):
  File "D:\Projects\Fast_API\blog_app\backend\app\core\database.py", line 21, in get_db
    yield session
  File "C:\Users\Admin\AppData\Roaming\Python\Python312\site-packages\fastapi\routing.py", line 278, in app
    raw_response = await run_endpoint_function(
                   ^^^^^^^^^^^^^^^^^^^^^^^^^^^^
  File "C:\Users\Admin\AppData\Roaming\Python\Python312\site-packages\fastapi\routing.py", line 191, in run_endpoint_function
    return await dependant.call(**values)
           ^^^^^^^^^^^^^^^^^^^^^^^^^^^^^^
  File "D:\Projects\Fast_API\blog_app\backend\app\routers\subcategories.py", line 42, in create_subcategory_route
    raise he
  File "D:\Projects\Fast_API\blog_app\backend\app\routers\subcategories.py", line 28, in create_subcategory_route
    raise HTTPException(
fastapi.exceptions.HTTPException: 400: Subcategory names already exist: New Sample Subcategory
ERROR 2024-09-24 10:37:39 root Error fetching subcategories for category ID 1: Multiple exceptions: [Errno 10061] Connect call failed ('::1', 5432, 0, 0), [Errno 10061] Connect call failed ('127.0.0.1', 5432)
Traceback (most recent call last):
  File "D:\Projects\Fast_API\blog_app\backend\app\services\subcategories.py", line 143, in get_subcategories_by_category_id
    category_result = await db.execute(select(Category).where(Category.id == category_id))
                      ^^^^^^^^^^^^^^^^^^^^^^^^^^^^^^^^^^^^^^^^^^^^^^^^^^^^^^^^^^^^^^^^^^^^
  File "C:\Users\Admin\AppData\Roaming\Python\Python312\site-packages\sqlalchemy\ext\asyncio\session.py", line 461, in execute
    result = await greenlet_spawn(
             ^^^^^^^^^^^^^^^^^^^^^
  File "C:\Users\Admin\AppData\Roaming\Python\Python312\site-packages\sqlalchemy\util\_concurrency_py3k.py", line 201, in greenlet_spawn
    result = context.throw(*sys.exc_info())
             ^^^^^^^^^^^^^^^^^^^^^^^^^^^^^^
  File "C:\Users\Admin\AppData\Roaming\Python\Python312\site-packages\sqlalchemy\orm\session.py", line 2362, in execute
    return self._execute_internal(
           ^^^^^^^^^^^^^^^^^^^^^^^
  File "C:\Users\Admin\AppData\Roaming\Python\Python312\site-packages\sqlalchemy\orm\session.py", line 2237, in _execute_internal
    conn = self._connection_for_bind(bind)
           ^^^^^^^^^^^^^^^^^^^^^^^^^^^^^^^
  File "C:\Users\Admin\AppData\Roaming\Python\Python312\site-packages\sqlalchemy\orm\session.py", line 2106, in _connection_for_bind
    return trans._connection_for_bind(engine, execution_options)
           ^^^^^^^^^^^^^^^^^^^^^^^^^^^^^^^^^^^^^^^^^^^^^^^^^^^^^
  File "<string>", line 2, in _connection_for_bind
  File "C:\Users\Admin\AppData\Roaming\Python\Python312\site-packages\sqlalchemy\orm\state_changes.py", line 139, in _go
    ret_value = fn(self, *arg, **kw)
                ^^^^^^^^^^^^^^^^^^^^
  File "C:\Users\Admin\AppData\Roaming\Python\Python312\site-packages\sqlalchemy\orm\session.py", line 1189, in _connection_for_bind
    conn = bind.connect()
           ^^^^^^^^^^^^^^
  File "C:\Users\Admin\AppData\Roaming\Python\Python312\site-packages\sqlalchemy\engine\base.py", line 3278, in connect
    return self._connection_cls(self)
           ^^^^^^^^^^^^^^^^^^^^^^^^^^
  File "C:\Users\Admin\AppData\Roaming\Python\Python312\site-packages\sqlalchemy\engine\base.py", line 146, in __init__
    self._dbapi_connection = engine.raw_connection()
                             ^^^^^^^^^^^^^^^^^^^^^^^
  File "C:\Users\Admin\AppData\Roaming\Python\Python312\site-packages\sqlalchemy\engine\base.py", line 3302, in raw_connection
    return self.pool.connect()
           ^^^^^^^^^^^^^^^^^^^
  File "C:\Users\Admin\AppData\Roaming\Python\Python312\site-packages\sqlalchemy\pool\base.py", line 449, in connect
    return _ConnectionFairy._checkout(self)
           ^^^^^^^^^^^^^^^^^^^^^^^^^^^^^^^^
  File "C:\Users\Admin\AppData\Roaming\Python\Python312\site-packages\sqlalchemy\pool\base.py", line 1263, in _checkout
    fairy = _ConnectionRecord.checkout(pool)
            ^^^^^^^^^^^^^^^^^^^^^^^^^^^^^^^^
  File "C:\Users\Admin\AppData\Roaming\Python\Python312\site-packages\sqlalchemy\pool\base.py", line 712, in checkout
    rec = pool._do_get()
          ^^^^^^^^^^^^^^
  File "C:\Users\Admin\AppData\Roaming\Python\Python312\site-packages\sqlalchemy\pool\impl.py", line 179, in _do_get
    with util.safe_reraise():
  File "C:\Users\Admin\AppData\Roaming\Python\Python312\site-packages\sqlalchemy\util\langhelpers.py", line 146, in __exit__
    raise exc_value.with_traceback(exc_tb)
  File "C:\Users\Admin\AppData\Roaming\Python\Python312\site-packages\sqlalchemy\pool\impl.py", line 177, in _do_get
    return self._create_connection()
           ^^^^^^^^^^^^^^^^^^^^^^^^^
  File "C:\Users\Admin\AppData\Roaming\Python\Python312\site-packages\sqlalchemy\pool\base.py", line 390, in _create_connection
    return _ConnectionRecord(self)
           ^^^^^^^^^^^^^^^^^^^^^^^
  File "C:\Users\Admin\AppData\Roaming\Python\Python312\site-packages\sqlalchemy\pool\base.py", line 674, in __init__
    self.__connect()
  File "C:\Users\Admin\AppData\Roaming\Python\Python312\site-packages\sqlalchemy\pool\base.py", line 900, in __connect
    with util.safe_reraise():
  File "C:\Users\Admin\AppData\Roaming\Python\Python312\site-packages\sqlalchemy\util\langhelpers.py", line 146, in __exit__
    raise exc_value.with_traceback(exc_tb)
  File "C:\Users\Admin\AppData\Roaming\Python\Python312\site-packages\sqlalchemy\pool\base.py", line 896, in __connect
    self.dbapi_connection = connection = pool._invoke_creator(self)
                                         ^^^^^^^^^^^^^^^^^^^^^^^^^^
  File "C:\Users\Admin\AppData\Roaming\Python\Python312\site-packages\sqlalchemy\engine\create.py", line 643, in connect
    return dialect.connect(*cargs, **cparams)
           ^^^^^^^^^^^^^^^^^^^^^^^^^^^^^^^^^^
  File "C:\Users\Admin\AppData\Roaming\Python\Python312\site-packages\sqlalchemy\engine\default.py", line 621, in connect
    return self.loaded_dbapi.connect(*cargs, **cparams)
           ^^^^^^^^^^^^^^^^^^^^^^^^^^^^^^^^^^^^^^^^^^^^
  File "C:\Users\Admin\AppData\Roaming\Python\Python312\site-packages\sqlalchemy\dialects\postgresql\asyncpg.py", line 953, in connect
    await_only(creator_fn(*arg, **kw)),
    ^^^^^^^^^^^^^^^^^^^^^^^^^^^^^^^^^^
  File "C:\Users\Admin\AppData\Roaming\Python\Python312\site-packages\sqlalchemy\util\_concurrency_py3k.py", line 132, in await_only
    return current.parent.switch(awaitable)  # type: ignore[no-any-return,attr-defined] # noqa: E501
           ^^^^^^^^^^^^^^^^^^^^^^^^^^^^^^^^
  File "C:\Users\Admin\AppData\Roaming\Python\Python312\site-packages\sqlalchemy\util\_concurrency_py3k.py", line 196, in greenlet_spawn
    value = await result
            ^^^^^^^^^^^^
  File "C:\Users\Admin\AppData\Roaming\Python\Python312\site-packages\asyncpg\connection.py", line 2329, in connect
    return await connect_utils._connect(
           ^^^^^^^^^^^^^^^^^^^^^^^^^^^^^
  File "C:\Users\Admin\AppData\Roaming\Python\Python312\site-packages\asyncpg\connect_utils.py", line 1017, in _connect
    raise last_error or exceptions.TargetServerAttributeNotMatched(
  File "C:\Users\Admin\AppData\Roaming\Python\Python312\site-packages\asyncpg\connect_utils.py", line 991, in _connect
    conn = await _connect_addr(
           ^^^^^^^^^^^^^^^^^^^^
  File "C:\Users\Admin\AppData\Roaming\Python\Python312\site-packages\asyncpg\connect_utils.py", line 828, in _connect_addr
    return await __connect_addr(params, True, *args)
           ^^^^^^^^^^^^^^^^^^^^^^^^^^^^^^^^^^^^^^^^^
  File "C:\Users\Admin\AppData\Roaming\Python\Python312\site-packages\asyncpg\connect_utils.py", line 873, in __connect_addr
    tr, pr = await connector
             ^^^^^^^^^^^^^^^
  File "C:\Users\Admin\AppData\Roaming\Python\Python312\site-packages\asyncpg\connect_utils.py", line 744, in _create_ssl_connection
    tr, pr = await loop.create_connection(
             ^^^^^^^^^^^^^^^^^^^^^^^^^^^^^
  File "D:\installed_software\anaconda3\envs\myenv3\Lib\asyncio\base_events.py", line 1130, in create_connection
    raise OSError('Multiple exceptions: {}'.format(
OSError: Multiple exceptions: [Errno 10061] Connect call failed ('::1', 5432, 0, 0), [Errno 10061] Connect call failed ('127.0.0.1', 5432)
ERROR 2024-09-24 10:37:39 root Unexpected error: 500: Failed to fetch subcategories for the category.
Traceback (most recent call last):
  File "D:\Projects\Fast_API\blog_app\backend\app\services\subcategories.py", line 143, in get_subcategories_by_category_id
    category_result = await db.execute(select(Category).where(Category.id == category_id))
                      ^^^^^^^^^^^^^^^^^^^^^^^^^^^^^^^^^^^^^^^^^^^^^^^^^^^^^^^^^^^^^^^^^^^^
  File "C:\Users\Admin\AppData\Roaming\Python\Python312\site-packages\sqlalchemy\ext\asyncio\session.py", line 461, in execute
    result = await greenlet_spawn(
             ^^^^^^^^^^^^^^^^^^^^^
  File "C:\Users\Admin\AppData\Roaming\Python\Python312\site-packages\sqlalchemy\util\_concurrency_py3k.py", line 201, in greenlet_spawn
    result = context.throw(*sys.exc_info())
             ^^^^^^^^^^^^^^^^^^^^^^^^^^^^^^
  File "C:\Users\Admin\AppData\Roaming\Python\Python312\site-packages\sqlalchemy\orm\session.py", line 2362, in execute
    return self._execute_internal(
           ^^^^^^^^^^^^^^^^^^^^^^^
  File "C:\Users\Admin\AppData\Roaming\Python\Python312\site-packages\sqlalchemy\orm\session.py", line 2237, in _execute_internal
    conn = self._connection_for_bind(bind)
           ^^^^^^^^^^^^^^^^^^^^^^^^^^^^^^^
  File "C:\Users\Admin\AppData\Roaming\Python\Python312\site-packages\sqlalchemy\orm\session.py", line 2106, in _connection_for_bind
    return trans._connection_for_bind(engine, execution_options)
           ^^^^^^^^^^^^^^^^^^^^^^^^^^^^^^^^^^^^^^^^^^^^^^^^^^^^^
  File "<string>", line 2, in _connection_for_bind
  File "C:\Users\Admin\AppData\Roaming\Python\Python312\site-packages\sqlalchemy\orm\state_changes.py", line 139, in _go
    ret_value = fn(self, *arg, **kw)
                ^^^^^^^^^^^^^^^^^^^^
  File "C:\Users\Admin\AppData\Roaming\Python\Python312\site-packages\sqlalchemy\orm\session.py", line 1189, in _connection_for_bind
    conn = bind.connect()
           ^^^^^^^^^^^^^^
  File "C:\Users\Admin\AppData\Roaming\Python\Python312\site-packages\sqlalchemy\engine\base.py", line 3278, in connect
    return self._connection_cls(self)
           ^^^^^^^^^^^^^^^^^^^^^^^^^^
  File "C:\Users\Admin\AppData\Roaming\Python\Python312\site-packages\sqlalchemy\engine\base.py", line 146, in __init__
    self._dbapi_connection = engine.raw_connection()
                             ^^^^^^^^^^^^^^^^^^^^^^^
  File "C:\Users\Admin\AppData\Roaming\Python\Python312\site-packages\sqlalchemy\engine\base.py", line 3302, in raw_connection
    return self.pool.connect()
           ^^^^^^^^^^^^^^^^^^^
  File "C:\Users\Admin\AppData\Roaming\Python\Python312\site-packages\sqlalchemy\pool\base.py", line 449, in connect
    return _ConnectionFairy._checkout(self)
           ^^^^^^^^^^^^^^^^^^^^^^^^^^^^^^^^
  File "C:\Users\Admin\AppData\Roaming\Python\Python312\site-packages\sqlalchemy\pool\base.py", line 1263, in _checkout
    fairy = _ConnectionRecord.checkout(pool)
            ^^^^^^^^^^^^^^^^^^^^^^^^^^^^^^^^
  File "C:\Users\Admin\AppData\Roaming\Python\Python312\site-packages\sqlalchemy\pool\base.py", line 712, in checkout
    rec = pool._do_get()
          ^^^^^^^^^^^^^^
  File "C:\Users\Admin\AppData\Roaming\Python\Python312\site-packages\sqlalchemy\pool\impl.py", line 179, in _do_get
    with util.safe_reraise():
  File "C:\Users\Admin\AppData\Roaming\Python\Python312\site-packages\sqlalchemy\util\langhelpers.py", line 146, in __exit__
    raise exc_value.with_traceback(exc_tb)
  File "C:\Users\Admin\AppData\Roaming\Python\Python312\site-packages\sqlalchemy\pool\impl.py", line 177, in _do_get
    return self._create_connection()
           ^^^^^^^^^^^^^^^^^^^^^^^^^
  File "C:\Users\Admin\AppData\Roaming\Python\Python312\site-packages\sqlalchemy\pool\base.py", line 390, in _create_connection
    return _ConnectionRecord(self)
           ^^^^^^^^^^^^^^^^^^^^^^^
  File "C:\Users\Admin\AppData\Roaming\Python\Python312\site-packages\sqlalchemy\pool\base.py", line 674, in __init__
    self.__connect()
  File "C:\Users\Admin\AppData\Roaming\Python\Python312\site-packages\sqlalchemy\pool\base.py", line 900, in __connect
    with util.safe_reraise():
  File "C:\Users\Admin\AppData\Roaming\Python\Python312\site-packages\sqlalchemy\util\langhelpers.py", line 146, in __exit__
    raise exc_value.with_traceback(exc_tb)
  File "C:\Users\Admin\AppData\Roaming\Python\Python312\site-packages\sqlalchemy\pool\base.py", line 896, in __connect
    self.dbapi_connection = connection = pool._invoke_creator(self)
                                         ^^^^^^^^^^^^^^^^^^^^^^^^^^
  File "C:\Users\Admin\AppData\Roaming\Python\Python312\site-packages\sqlalchemy\engine\create.py", line 643, in connect
    return dialect.connect(*cargs, **cparams)
           ^^^^^^^^^^^^^^^^^^^^^^^^^^^^^^^^^^
  File "C:\Users\Admin\AppData\Roaming\Python\Python312\site-packages\sqlalchemy\engine\default.py", line 621, in connect
    return self.loaded_dbapi.connect(*cargs, **cparams)
           ^^^^^^^^^^^^^^^^^^^^^^^^^^^^^^^^^^^^^^^^^^^^
  File "C:\Users\Admin\AppData\Roaming\Python\Python312\site-packages\sqlalchemy\dialects\postgresql\asyncpg.py", line 953, in connect
    await_only(creator_fn(*arg, **kw)),
    ^^^^^^^^^^^^^^^^^^^^^^^^^^^^^^^^^^
  File "C:\Users\Admin\AppData\Roaming\Python\Python312\site-packages\sqlalchemy\util\_concurrency_py3k.py", line 132, in await_only
    return current.parent.switch(awaitable)  # type: ignore[no-any-return,attr-defined] # noqa: E501
           ^^^^^^^^^^^^^^^^^^^^^^^^^^^^^^^^
  File "C:\Users\Admin\AppData\Roaming\Python\Python312\site-packages\sqlalchemy\util\_concurrency_py3k.py", line 196, in greenlet_spawn
    value = await result
            ^^^^^^^^^^^^
  File "C:\Users\Admin\AppData\Roaming\Python\Python312\site-packages\asyncpg\connection.py", line 2329, in connect
    return await connect_utils._connect(
           ^^^^^^^^^^^^^^^^^^^^^^^^^^^^^
  File "C:\Users\Admin\AppData\Roaming\Python\Python312\site-packages\asyncpg\connect_utils.py", line 1017, in _connect
    raise last_error or exceptions.TargetServerAttributeNotMatched(
  File "C:\Users\Admin\AppData\Roaming\Python\Python312\site-packages\asyncpg\connect_utils.py", line 991, in _connect
    conn = await _connect_addr(
           ^^^^^^^^^^^^^^^^^^^^
  File "C:\Users\Admin\AppData\Roaming\Python\Python312\site-packages\asyncpg\connect_utils.py", line 828, in _connect_addr
    return await __connect_addr(params, True, *args)
           ^^^^^^^^^^^^^^^^^^^^^^^^^^^^^^^^^^^^^^^^^
  File "C:\Users\Admin\AppData\Roaming\Python\Python312\site-packages\asyncpg\connect_utils.py", line 873, in __connect_addr
    tr, pr = await connector
             ^^^^^^^^^^^^^^^
  File "C:\Users\Admin\AppData\Roaming\Python\Python312\site-packages\asyncpg\connect_utils.py", line 744, in _create_ssl_connection
    tr, pr = await loop.create_connection(
             ^^^^^^^^^^^^^^^^^^^^^^^^^^^^^
  File "D:\installed_software\anaconda3\envs\myenv3\Lib\asyncio\base_events.py", line 1130, in create_connection
    raise OSError('Multiple exceptions: {}'.format(
OSError: Multiple exceptions: [Errno 10061] Connect call failed ('::1', 5432, 0, 0), [Errno 10061] Connect call failed ('127.0.0.1', 5432)

During handling of the above exception, another exception occurred:

Traceback (most recent call last):
  File "D:\Projects\Fast_API\blog_app\backend\app\core\database.py", line 21, in get_db
    yield session
  File "C:\Users\Admin\AppData\Roaming\Python\Python312\site-packages\fastapi\routing.py", line 278, in app
    raw_response = await run_endpoint_function(
                   ^^^^^^^^^^^^^^^^^^^^^^^^^^^^
  File "C:\Users\Admin\AppData\Roaming\Python\Python312\site-packages\fastapi\routing.py", line 191, in run_endpoint_function
    return await dependant.call(**values)
           ^^^^^^^^^^^^^^^^^^^^^^^^^^^^^^
  File "D:\Projects\Fast_API\blog_app\backend\app\routers\subcategories.py", line 155, in get_subcategories_for_category
    raise e
  File "D:\Projects\Fast_API\blog_app\backend\app\routers\subcategories.py", line 144, in get_subcategories_for_category
    result = await get_subcategories_by_category_id(db, category_id, skip, limit)
             ^^^^^^^^^^^^^^^^^^^^^^^^^^^^^^^^^^^^^^^^^^^^^^^^^^^^^^^^^^^^^^^^^^^^
  File "D:\Projects\Fast_API\blog_app\backend\app\services\subcategories.py", line 174, in get_subcategories_by_category_id
    raise HTTPException(
fastapi.exceptions.HTTPException: 500: Failed to fetch subcategories for the category.
ERROR 2024-09-24 10:38:39 root Error fetching subcategories for category ID 1: Multiple exceptions: [Errno 10061] Connect call failed ('::1', 5432, 0, 0), [Errno 10061] Connect call failed ('127.0.0.1', 5432)
Traceback (most recent call last):
  File "D:\Projects\Fast_API\blog_app\backend\app\services\subcategories.py", line 143, in get_subcategories_by_category_id
    category_result = await db.execute(select(Category).where(Category.id == category_id))
                      ^^^^^^^^^^^^^^^^^^^^^^^^^^^^^^^^^^^^^^^^^^^^^^^^^^^^^^^^^^^^^^^^^^^^
  File "C:\Users\Admin\AppData\Roaming\Python\Python312\site-packages\sqlalchemy\ext\asyncio\session.py", line 461, in execute
    result = await greenlet_spawn(
             ^^^^^^^^^^^^^^^^^^^^^
  File "C:\Users\Admin\AppData\Roaming\Python\Python312\site-packages\sqlalchemy\util\_concurrency_py3k.py", line 201, in greenlet_spawn
    result = context.throw(*sys.exc_info())
             ^^^^^^^^^^^^^^^^^^^^^^^^^^^^^^
  File "C:\Users\Admin\AppData\Roaming\Python\Python312\site-packages\sqlalchemy\orm\session.py", line 2362, in execute
    return self._execute_internal(
           ^^^^^^^^^^^^^^^^^^^^^^^
  File "C:\Users\Admin\AppData\Roaming\Python\Python312\site-packages\sqlalchemy\orm\session.py", line 2237, in _execute_internal
    conn = self._connection_for_bind(bind)
           ^^^^^^^^^^^^^^^^^^^^^^^^^^^^^^^
  File "C:\Users\Admin\AppData\Roaming\Python\Python312\site-packages\sqlalchemy\orm\session.py", line 2106, in _connection_for_bind
    return trans._connection_for_bind(engine, execution_options)
           ^^^^^^^^^^^^^^^^^^^^^^^^^^^^^^^^^^^^^^^^^^^^^^^^^^^^^
  File "<string>", line 2, in _connection_for_bind
  File "C:\Users\Admin\AppData\Roaming\Python\Python312\site-packages\sqlalchemy\orm\state_changes.py", line 139, in _go
    ret_value = fn(self, *arg, **kw)
                ^^^^^^^^^^^^^^^^^^^^
  File "C:\Users\Admin\AppData\Roaming\Python\Python312\site-packages\sqlalchemy\orm\session.py", line 1189, in _connection_for_bind
    conn = bind.connect()
           ^^^^^^^^^^^^^^
  File "C:\Users\Admin\AppData\Roaming\Python\Python312\site-packages\sqlalchemy\engine\base.py", line 3278, in connect
    return self._connection_cls(self)
           ^^^^^^^^^^^^^^^^^^^^^^^^^^
  File "C:\Users\Admin\AppData\Roaming\Python\Python312\site-packages\sqlalchemy\engine\base.py", line 146, in __init__
    self._dbapi_connection = engine.raw_connection()
                             ^^^^^^^^^^^^^^^^^^^^^^^
  File "C:\Users\Admin\AppData\Roaming\Python\Python312\site-packages\sqlalchemy\engine\base.py", line 3302, in raw_connection
    return self.pool.connect()
           ^^^^^^^^^^^^^^^^^^^
  File "C:\Users\Admin\AppData\Roaming\Python\Python312\site-packages\sqlalchemy\pool\base.py", line 449, in connect
    return _ConnectionFairy._checkout(self)
           ^^^^^^^^^^^^^^^^^^^^^^^^^^^^^^^^
  File "C:\Users\Admin\AppData\Roaming\Python\Python312\site-packages\sqlalchemy\pool\base.py", line 1263, in _checkout
    fairy = _ConnectionRecord.checkout(pool)
            ^^^^^^^^^^^^^^^^^^^^^^^^^^^^^^^^
  File "C:\Users\Admin\AppData\Roaming\Python\Python312\site-packages\sqlalchemy\pool\base.py", line 712, in checkout
    rec = pool._do_get()
          ^^^^^^^^^^^^^^
  File "C:\Users\Admin\AppData\Roaming\Python\Python312\site-packages\sqlalchemy\pool\impl.py", line 179, in _do_get
    with util.safe_reraise():
  File "C:\Users\Admin\AppData\Roaming\Python\Python312\site-packages\sqlalchemy\util\langhelpers.py", line 146, in __exit__
    raise exc_value.with_traceback(exc_tb)
  File "C:\Users\Admin\AppData\Roaming\Python\Python312\site-packages\sqlalchemy\pool\impl.py", line 177, in _do_get
    return self._create_connection()
           ^^^^^^^^^^^^^^^^^^^^^^^^^
  File "C:\Users\Admin\AppData\Roaming\Python\Python312\site-packages\sqlalchemy\pool\base.py", line 390, in _create_connection
    return _ConnectionRecord(self)
           ^^^^^^^^^^^^^^^^^^^^^^^
  File "C:\Users\Admin\AppData\Roaming\Python\Python312\site-packages\sqlalchemy\pool\base.py", line 674, in __init__
    self.__connect()
  File "C:\Users\Admin\AppData\Roaming\Python\Python312\site-packages\sqlalchemy\pool\base.py", line 900, in __connect
    with util.safe_reraise():
  File "C:\Users\Admin\AppData\Roaming\Python\Python312\site-packages\sqlalchemy\util\langhelpers.py", line 146, in __exit__
    raise exc_value.with_traceback(exc_tb)
  File "C:\Users\Admin\AppData\Roaming\Python\Python312\site-packages\sqlalchemy\pool\base.py", line 896, in __connect
    self.dbapi_connection = connection = pool._invoke_creator(self)
                                         ^^^^^^^^^^^^^^^^^^^^^^^^^^
  File "C:\Users\Admin\AppData\Roaming\Python\Python312\site-packages\sqlalchemy\engine\create.py", line 643, in connect
    return dialect.connect(*cargs, **cparams)
           ^^^^^^^^^^^^^^^^^^^^^^^^^^^^^^^^^^
  File "C:\Users\Admin\AppData\Roaming\Python\Python312\site-packages\sqlalchemy\engine\default.py", line 621, in connect
    return self.loaded_dbapi.connect(*cargs, **cparams)
           ^^^^^^^^^^^^^^^^^^^^^^^^^^^^^^^^^^^^^^^^^^^^
  File "C:\Users\Admin\AppData\Roaming\Python\Python312\site-packages\sqlalchemy\dialects\postgresql\asyncpg.py", line 953, in connect
    await_only(creator_fn(*arg, **kw)),
    ^^^^^^^^^^^^^^^^^^^^^^^^^^^^^^^^^^
  File "C:\Users\Admin\AppData\Roaming\Python\Python312\site-packages\sqlalchemy\util\_concurrency_py3k.py", line 132, in await_only
    return current.parent.switch(awaitable)  # type: ignore[no-any-return,attr-defined] # noqa: E501
           ^^^^^^^^^^^^^^^^^^^^^^^^^^^^^^^^
  File "C:\Users\Admin\AppData\Roaming\Python\Python312\site-packages\sqlalchemy\util\_concurrency_py3k.py", line 196, in greenlet_spawn
    value = await result
            ^^^^^^^^^^^^
  File "C:\Users\Admin\AppData\Roaming\Python\Python312\site-packages\asyncpg\connection.py", line 2329, in connect
    return await connect_utils._connect(
           ^^^^^^^^^^^^^^^^^^^^^^^^^^^^^
  File "C:\Users\Admin\AppData\Roaming\Python\Python312\site-packages\asyncpg\connect_utils.py", line 1017, in _connect
    raise last_error or exceptions.TargetServerAttributeNotMatched(
  File "C:\Users\Admin\AppData\Roaming\Python\Python312\site-packages\asyncpg\connect_utils.py", line 991, in _connect
    conn = await _connect_addr(
           ^^^^^^^^^^^^^^^^^^^^
  File "C:\Users\Admin\AppData\Roaming\Python\Python312\site-packages\asyncpg\connect_utils.py", line 828, in _connect_addr
    return await __connect_addr(params, True, *args)
           ^^^^^^^^^^^^^^^^^^^^^^^^^^^^^^^^^^^^^^^^^
  File "C:\Users\Admin\AppData\Roaming\Python\Python312\site-packages\asyncpg\connect_utils.py", line 873, in __connect_addr
    tr, pr = await connector
             ^^^^^^^^^^^^^^^
  File "C:\Users\Admin\AppData\Roaming\Python\Python312\site-packages\asyncpg\connect_utils.py", line 744, in _create_ssl_connection
    tr, pr = await loop.create_connection(
             ^^^^^^^^^^^^^^^^^^^^^^^^^^^^^
  File "D:\installed_software\anaconda3\envs\myenv3\Lib\asyncio\base_events.py", line 1130, in create_connection
    raise OSError('Multiple exceptions: {}'.format(
OSError: Multiple exceptions: [Errno 10061] Connect call failed ('::1', 5432, 0, 0), [Errno 10061] Connect call failed ('127.0.0.1', 5432)
ERROR 2024-09-24 10:38:39 root Unexpected error: 500: Failed to fetch subcategories for the category.
Traceback (most recent call last):
  File "D:\Projects\Fast_API\blog_app\backend\app\services\subcategories.py", line 143, in get_subcategories_by_category_id
    category_result = await db.execute(select(Category).where(Category.id == category_id))
                      ^^^^^^^^^^^^^^^^^^^^^^^^^^^^^^^^^^^^^^^^^^^^^^^^^^^^^^^^^^^^^^^^^^^^
  File "C:\Users\Admin\AppData\Roaming\Python\Python312\site-packages\sqlalchemy\ext\asyncio\session.py", line 461, in execute
    result = await greenlet_spawn(
             ^^^^^^^^^^^^^^^^^^^^^
  File "C:\Users\Admin\AppData\Roaming\Python\Python312\site-packages\sqlalchemy\util\_concurrency_py3k.py", line 201, in greenlet_spawn
    result = context.throw(*sys.exc_info())
             ^^^^^^^^^^^^^^^^^^^^^^^^^^^^^^
  File "C:\Users\Admin\AppData\Roaming\Python\Python312\site-packages\sqlalchemy\orm\session.py", line 2362, in execute
    return self._execute_internal(
           ^^^^^^^^^^^^^^^^^^^^^^^
  File "C:\Users\Admin\AppData\Roaming\Python\Python312\site-packages\sqlalchemy\orm\session.py", line 2237, in _execute_internal
    conn = self._connection_for_bind(bind)
           ^^^^^^^^^^^^^^^^^^^^^^^^^^^^^^^
  File "C:\Users\Admin\AppData\Roaming\Python\Python312\site-packages\sqlalchemy\orm\session.py", line 2106, in _connection_for_bind
    return trans._connection_for_bind(engine, execution_options)
           ^^^^^^^^^^^^^^^^^^^^^^^^^^^^^^^^^^^^^^^^^^^^^^^^^^^^^
  File "<string>", line 2, in _connection_for_bind
  File "C:\Users\Admin\AppData\Roaming\Python\Python312\site-packages\sqlalchemy\orm\state_changes.py", line 139, in _go
    ret_value = fn(self, *arg, **kw)
                ^^^^^^^^^^^^^^^^^^^^
  File "C:\Users\Admin\AppData\Roaming\Python\Python312\site-packages\sqlalchemy\orm\session.py", line 1189, in _connection_for_bind
    conn = bind.connect()
           ^^^^^^^^^^^^^^
  File "C:\Users\Admin\AppData\Roaming\Python\Python312\site-packages\sqlalchemy\engine\base.py", line 3278, in connect
    return self._connection_cls(self)
           ^^^^^^^^^^^^^^^^^^^^^^^^^^
  File "C:\Users\Admin\AppData\Roaming\Python\Python312\site-packages\sqlalchemy\engine\base.py", line 146, in __init__
    self._dbapi_connection = engine.raw_connection()
                             ^^^^^^^^^^^^^^^^^^^^^^^
  File "C:\Users\Admin\AppData\Roaming\Python\Python312\site-packages\sqlalchemy\engine\base.py", line 3302, in raw_connection
    return self.pool.connect()
           ^^^^^^^^^^^^^^^^^^^
  File "C:\Users\Admin\AppData\Roaming\Python\Python312\site-packages\sqlalchemy\pool\base.py", line 449, in connect
    return _ConnectionFairy._checkout(self)
           ^^^^^^^^^^^^^^^^^^^^^^^^^^^^^^^^
  File "C:\Users\Admin\AppData\Roaming\Python\Python312\site-packages\sqlalchemy\pool\base.py", line 1263, in _checkout
    fairy = _ConnectionRecord.checkout(pool)
            ^^^^^^^^^^^^^^^^^^^^^^^^^^^^^^^^
  File "C:\Users\Admin\AppData\Roaming\Python\Python312\site-packages\sqlalchemy\pool\base.py", line 712, in checkout
    rec = pool._do_get()
          ^^^^^^^^^^^^^^
  File "C:\Users\Admin\AppData\Roaming\Python\Python312\site-packages\sqlalchemy\pool\impl.py", line 179, in _do_get
    with util.safe_reraise():
  File "C:\Users\Admin\AppData\Roaming\Python\Python312\site-packages\sqlalchemy\util\langhelpers.py", line 146, in __exit__
    raise exc_value.with_traceback(exc_tb)
  File "C:\Users\Admin\AppData\Roaming\Python\Python312\site-packages\sqlalchemy\pool\impl.py", line 177, in _do_get
    return self._create_connection()
           ^^^^^^^^^^^^^^^^^^^^^^^^^
  File "C:\Users\Admin\AppData\Roaming\Python\Python312\site-packages\sqlalchemy\pool\base.py", line 390, in _create_connection
    return _ConnectionRecord(self)
           ^^^^^^^^^^^^^^^^^^^^^^^
  File "C:\Users\Admin\AppData\Roaming\Python\Python312\site-packages\sqlalchemy\pool\base.py", line 674, in __init__
    self.__connect()
  File "C:\Users\Admin\AppData\Roaming\Python\Python312\site-packages\sqlalchemy\pool\base.py", line 900, in __connect
    with util.safe_reraise():
  File "C:\Users\Admin\AppData\Roaming\Python\Python312\site-packages\sqlalchemy\util\langhelpers.py", line 146, in __exit__
    raise exc_value.with_traceback(exc_tb)
  File "C:\Users\Admin\AppData\Roaming\Python\Python312\site-packages\sqlalchemy\pool\base.py", line 896, in __connect
    self.dbapi_connection = connection = pool._invoke_creator(self)
                                         ^^^^^^^^^^^^^^^^^^^^^^^^^^
  File "C:\Users\Admin\AppData\Roaming\Python\Python312\site-packages\sqlalchemy\engine\create.py", line 643, in connect
    return dialect.connect(*cargs, **cparams)
           ^^^^^^^^^^^^^^^^^^^^^^^^^^^^^^^^^^
  File "C:\Users\Admin\AppData\Roaming\Python\Python312\site-packages\sqlalchemy\engine\default.py", line 621, in connect
    return self.loaded_dbapi.connect(*cargs, **cparams)
           ^^^^^^^^^^^^^^^^^^^^^^^^^^^^^^^^^^^^^^^^^^^^
  File "C:\Users\Admin\AppData\Roaming\Python\Python312\site-packages\sqlalchemy\dialects\postgresql\asyncpg.py", line 953, in connect
    await_only(creator_fn(*arg, **kw)),
    ^^^^^^^^^^^^^^^^^^^^^^^^^^^^^^^^^^
  File "C:\Users\Admin\AppData\Roaming\Python\Python312\site-packages\sqlalchemy\util\_concurrency_py3k.py", line 132, in await_only
    return current.parent.switch(awaitable)  # type: ignore[no-any-return,attr-defined] # noqa: E501
           ^^^^^^^^^^^^^^^^^^^^^^^^^^^^^^^^
  File "C:\Users\Admin\AppData\Roaming\Python\Python312\site-packages\sqlalchemy\util\_concurrency_py3k.py", line 196, in greenlet_spawn
    value = await result
            ^^^^^^^^^^^^
  File "C:\Users\Admin\AppData\Roaming\Python\Python312\site-packages\asyncpg\connection.py", line 2329, in connect
    return await connect_utils._connect(
           ^^^^^^^^^^^^^^^^^^^^^^^^^^^^^
  File "C:\Users\Admin\AppData\Roaming\Python\Python312\site-packages\asyncpg\connect_utils.py", line 1017, in _connect
    raise last_error or exceptions.TargetServerAttributeNotMatched(
  File "C:\Users\Admin\AppData\Roaming\Python\Python312\site-packages\asyncpg\connect_utils.py", line 991, in _connect
    conn = await _connect_addr(
           ^^^^^^^^^^^^^^^^^^^^
  File "C:\Users\Admin\AppData\Roaming\Python\Python312\site-packages\asyncpg\connect_utils.py", line 828, in _connect_addr
    return await __connect_addr(params, True, *args)
           ^^^^^^^^^^^^^^^^^^^^^^^^^^^^^^^^^^^^^^^^^
  File "C:\Users\Admin\AppData\Roaming\Python\Python312\site-packages\asyncpg\connect_utils.py", line 873, in __connect_addr
    tr, pr = await connector
             ^^^^^^^^^^^^^^^
  File "C:\Users\Admin\AppData\Roaming\Python\Python312\site-packages\asyncpg\connect_utils.py", line 744, in _create_ssl_connection
    tr, pr = await loop.create_connection(
             ^^^^^^^^^^^^^^^^^^^^^^^^^^^^^
  File "D:\installed_software\anaconda3\envs\myenv3\Lib\asyncio\base_events.py", line 1130, in create_connection
    raise OSError('Multiple exceptions: {}'.format(
OSError: Multiple exceptions: [Errno 10061] Connect call failed ('::1', 5432, 0, 0), [Errno 10061] Connect call failed ('127.0.0.1', 5432)

During handling of the above exception, another exception occurred:

Traceback (most recent call last):
  File "D:\Projects\Fast_API\blog_app\backend\app\core\database.py", line 21, in get_db
    yield session
  File "C:\Users\Admin\AppData\Roaming\Python\Python312\site-packages\fastapi\routing.py", line 278, in app
    raw_response = await run_endpoint_function(
                   ^^^^^^^^^^^^^^^^^^^^^^^^^^^^
  File "C:\Users\Admin\AppData\Roaming\Python\Python312\site-packages\fastapi\routing.py", line 191, in run_endpoint_function
    return await dependant.call(**values)
           ^^^^^^^^^^^^^^^^^^^^^^^^^^^^^^
  File "D:\Projects\Fast_API\blog_app\backend\app\routers\subcategories.py", line 156, in get_subcategories_for_category
    raise e
  File "D:\Projects\Fast_API\blog_app\backend\app\routers\subcategories.py", line 144, in get_subcategories_for_category
    result = await get_subcategories_by_category_id(db, category_id, skip, limit)
             ^^^^^^^^^^^^^^^^^^^^^^^^^^^^^^^^^^^^^^^^^^^^^^^^^^^^^^^^^^^^^^^^^^^^
  File "D:\Projects\Fast_API\blog_app\backend\app\services\subcategories.py", line 174, in get_subcategories_by_category_id
    raise HTTPException(
fastapi.exceptions.HTTPException: 500: Failed to fetch subcategories for the category.
ERROR 2024-09-24 10:50:48 root Error fetching subcategories for category ID 1: Multiple exceptions: [Errno 10061] Connect call failed ('::1', 5432, 0, 0), [Errno 10061] Connect call failed ('127.0.0.1', 5432)
Traceback (most recent call last):
  File "D:\Projects\Fast_API\blog_app\backend\app\services\subcategories.py", line 143, in get_subcategories_by_category_id
    category_result = await db.execute(select(Category).where(Category.id == category_id))
                      ^^^^^^^^^^^^^^^^^^^^^^^^^^^^^^^^^^^^^^^^^^^^^^^^^^^^^^^^^^^^^^^^^^^^
  File "C:\Users\Admin\AppData\Roaming\Python\Python312\site-packages\sqlalchemy\ext\asyncio\session.py", line 461, in execute
    result = await greenlet_spawn(
             ^^^^^^^^^^^^^^^^^^^^^
  File "C:\Users\Admin\AppData\Roaming\Python\Python312\site-packages\sqlalchemy\util\_concurrency_py3k.py", line 201, in greenlet_spawn
    result = context.throw(*sys.exc_info())
             ^^^^^^^^^^^^^^^^^^^^^^^^^^^^^^
  File "C:\Users\Admin\AppData\Roaming\Python\Python312\site-packages\sqlalchemy\orm\session.py", line 2362, in execute
    return self._execute_internal(
           ^^^^^^^^^^^^^^^^^^^^^^^
  File "C:\Users\Admin\AppData\Roaming\Python\Python312\site-packages\sqlalchemy\orm\session.py", line 2237, in _execute_internal
    conn = self._connection_for_bind(bind)
           ^^^^^^^^^^^^^^^^^^^^^^^^^^^^^^^
  File "C:\Users\Admin\AppData\Roaming\Python\Python312\site-packages\sqlalchemy\orm\session.py", line 2106, in _connection_for_bind
    return trans._connection_for_bind(engine, execution_options)
           ^^^^^^^^^^^^^^^^^^^^^^^^^^^^^^^^^^^^^^^^^^^^^^^^^^^^^
  File "<string>", line 2, in _connection_for_bind
  File "C:\Users\Admin\AppData\Roaming\Python\Python312\site-packages\sqlalchemy\orm\state_changes.py", line 139, in _go
    ret_value = fn(self, *arg, **kw)
                ^^^^^^^^^^^^^^^^^^^^
  File "C:\Users\Admin\AppData\Roaming\Python\Python312\site-packages\sqlalchemy\orm\session.py", line 1189, in _connection_for_bind
    conn = bind.connect()
           ^^^^^^^^^^^^^^
  File "C:\Users\Admin\AppData\Roaming\Python\Python312\site-packages\sqlalchemy\engine\base.py", line 3278, in connect
    return self._connection_cls(self)
           ^^^^^^^^^^^^^^^^^^^^^^^^^^
  File "C:\Users\Admin\AppData\Roaming\Python\Python312\site-packages\sqlalchemy\engine\base.py", line 146, in __init__
    self._dbapi_connection = engine.raw_connection()
                             ^^^^^^^^^^^^^^^^^^^^^^^
  File "C:\Users\Admin\AppData\Roaming\Python\Python312\site-packages\sqlalchemy\engine\base.py", line 3302, in raw_connection
    return self.pool.connect()
           ^^^^^^^^^^^^^^^^^^^
  File "C:\Users\Admin\AppData\Roaming\Python\Python312\site-packages\sqlalchemy\pool\base.py", line 449, in connect
    return _ConnectionFairy._checkout(self)
           ^^^^^^^^^^^^^^^^^^^^^^^^^^^^^^^^
  File "C:\Users\Admin\AppData\Roaming\Python\Python312\site-packages\sqlalchemy\pool\base.py", line 1263, in _checkout
    fairy = _ConnectionRecord.checkout(pool)
            ^^^^^^^^^^^^^^^^^^^^^^^^^^^^^^^^
  File "C:\Users\Admin\AppData\Roaming\Python\Python312\site-packages\sqlalchemy\pool\base.py", line 712, in checkout
    rec = pool._do_get()
          ^^^^^^^^^^^^^^
  File "C:\Users\Admin\AppData\Roaming\Python\Python312\site-packages\sqlalchemy\pool\impl.py", line 179, in _do_get
    with util.safe_reraise():
  File "C:\Users\Admin\AppData\Roaming\Python\Python312\site-packages\sqlalchemy\util\langhelpers.py", line 146, in __exit__
    raise exc_value.with_traceback(exc_tb)
  File "C:\Users\Admin\AppData\Roaming\Python\Python312\site-packages\sqlalchemy\pool\impl.py", line 177, in _do_get
    return self._create_connection()
           ^^^^^^^^^^^^^^^^^^^^^^^^^
  File "C:\Users\Admin\AppData\Roaming\Python\Python312\site-packages\sqlalchemy\pool\base.py", line 390, in _create_connection
    return _ConnectionRecord(self)
           ^^^^^^^^^^^^^^^^^^^^^^^
  File "C:\Users\Admin\AppData\Roaming\Python\Python312\site-packages\sqlalchemy\pool\base.py", line 674, in __init__
    self.__connect()
  File "C:\Users\Admin\AppData\Roaming\Python\Python312\site-packages\sqlalchemy\pool\base.py", line 900, in __connect
    with util.safe_reraise():
  File "C:\Users\Admin\AppData\Roaming\Python\Python312\site-packages\sqlalchemy\util\langhelpers.py", line 146, in __exit__
    raise exc_value.with_traceback(exc_tb)
  File "C:\Users\Admin\AppData\Roaming\Python\Python312\site-packages\sqlalchemy\pool\base.py", line 896, in __connect
    self.dbapi_connection = connection = pool._invoke_creator(self)
                                         ^^^^^^^^^^^^^^^^^^^^^^^^^^
  File "C:\Users\Admin\AppData\Roaming\Python\Python312\site-packages\sqlalchemy\engine\create.py", line 643, in connect
    return dialect.connect(*cargs, **cparams)
           ^^^^^^^^^^^^^^^^^^^^^^^^^^^^^^^^^^
  File "C:\Users\Admin\AppData\Roaming\Python\Python312\site-packages\sqlalchemy\engine\default.py", line 621, in connect
    return self.loaded_dbapi.connect(*cargs, **cparams)
           ^^^^^^^^^^^^^^^^^^^^^^^^^^^^^^^^^^^^^^^^^^^^
  File "C:\Users\Admin\AppData\Roaming\Python\Python312\site-packages\sqlalchemy\dialects\postgresql\asyncpg.py", line 953, in connect
    await_only(creator_fn(*arg, **kw)),
    ^^^^^^^^^^^^^^^^^^^^^^^^^^^^^^^^^^
  File "C:\Users\Admin\AppData\Roaming\Python\Python312\site-packages\sqlalchemy\util\_concurrency_py3k.py", line 132, in await_only
    return current.parent.switch(awaitable)  # type: ignore[no-any-return,attr-defined] # noqa: E501
           ^^^^^^^^^^^^^^^^^^^^^^^^^^^^^^^^
  File "C:\Users\Admin\AppData\Roaming\Python\Python312\site-packages\sqlalchemy\util\_concurrency_py3k.py", line 196, in greenlet_spawn
    value = await result
            ^^^^^^^^^^^^
  File "C:\Users\Admin\AppData\Roaming\Python\Python312\site-packages\asyncpg\connection.py", line 2329, in connect
    return await connect_utils._connect(
           ^^^^^^^^^^^^^^^^^^^^^^^^^^^^^
  File "C:\Users\Admin\AppData\Roaming\Python\Python312\site-packages\asyncpg\connect_utils.py", line 1017, in _connect
    raise last_error or exceptions.TargetServerAttributeNotMatched(
  File "C:\Users\Admin\AppData\Roaming\Python\Python312\site-packages\asyncpg\connect_utils.py", line 991, in _connect
    conn = await _connect_addr(
           ^^^^^^^^^^^^^^^^^^^^
  File "C:\Users\Admin\AppData\Roaming\Python\Python312\site-packages\asyncpg\connect_utils.py", line 828, in _connect_addr
    return await __connect_addr(params, True, *args)
           ^^^^^^^^^^^^^^^^^^^^^^^^^^^^^^^^^^^^^^^^^
  File "C:\Users\Admin\AppData\Roaming\Python\Python312\site-packages\asyncpg\connect_utils.py", line 873, in __connect_addr
    tr, pr = await connector
             ^^^^^^^^^^^^^^^
  File "C:\Users\Admin\AppData\Roaming\Python\Python312\site-packages\asyncpg\connect_utils.py", line 744, in _create_ssl_connection
    tr, pr = await loop.create_connection(
             ^^^^^^^^^^^^^^^^^^^^^^^^^^^^^
  File "D:\installed_software\anaconda3\envs\myenv3\Lib\asyncio\base_events.py", line 1130, in create_connection
    raise OSError('Multiple exceptions: {}'.format(
OSError: Multiple exceptions: [Errno 10061] Connect call failed ('::1', 5432, 0, 0), [Errno 10061] Connect call failed ('127.0.0.1', 5432)
ERROR 2024-09-24 10:50:48 root Unexpected error: 500: Failed to fetch subcategories for the category.
Traceback (most recent call last):
  File "D:\Projects\Fast_API\blog_app\backend\app\services\subcategories.py", line 143, in get_subcategories_by_category_id
    category_result = await db.execute(select(Category).where(Category.id == category_id))
                      ^^^^^^^^^^^^^^^^^^^^^^^^^^^^^^^^^^^^^^^^^^^^^^^^^^^^^^^^^^^^^^^^^^^^
  File "C:\Users\Admin\AppData\Roaming\Python\Python312\site-packages\sqlalchemy\ext\asyncio\session.py", line 461, in execute
    result = await greenlet_spawn(
             ^^^^^^^^^^^^^^^^^^^^^
  File "C:\Users\Admin\AppData\Roaming\Python\Python312\site-packages\sqlalchemy\util\_concurrency_py3k.py", line 201, in greenlet_spawn
    result = context.throw(*sys.exc_info())
             ^^^^^^^^^^^^^^^^^^^^^^^^^^^^^^
  File "C:\Users\Admin\AppData\Roaming\Python\Python312\site-packages\sqlalchemy\orm\session.py", line 2362, in execute
    return self._execute_internal(
           ^^^^^^^^^^^^^^^^^^^^^^^
  File "C:\Users\Admin\AppData\Roaming\Python\Python312\site-packages\sqlalchemy\orm\session.py", line 2237, in _execute_internal
    conn = self._connection_for_bind(bind)
           ^^^^^^^^^^^^^^^^^^^^^^^^^^^^^^^
  File "C:\Users\Admin\AppData\Roaming\Python\Python312\site-packages\sqlalchemy\orm\session.py", line 2106, in _connection_for_bind
    return trans._connection_for_bind(engine, execution_options)
           ^^^^^^^^^^^^^^^^^^^^^^^^^^^^^^^^^^^^^^^^^^^^^^^^^^^^^
  File "<string>", line 2, in _connection_for_bind
  File "C:\Users\Admin\AppData\Roaming\Python\Python312\site-packages\sqlalchemy\orm\state_changes.py", line 139, in _go
    ret_value = fn(self, *arg, **kw)
                ^^^^^^^^^^^^^^^^^^^^
  File "C:\Users\Admin\AppData\Roaming\Python\Python312\site-packages\sqlalchemy\orm\session.py", line 1189, in _connection_for_bind
    conn = bind.connect()
           ^^^^^^^^^^^^^^
  File "C:\Users\Admin\AppData\Roaming\Python\Python312\site-packages\sqlalchemy\engine\base.py", line 3278, in connect
    return self._connection_cls(self)
           ^^^^^^^^^^^^^^^^^^^^^^^^^^
  File "C:\Users\Admin\AppData\Roaming\Python\Python312\site-packages\sqlalchemy\engine\base.py", line 146, in __init__
    self._dbapi_connection = engine.raw_connection()
                             ^^^^^^^^^^^^^^^^^^^^^^^
  File "C:\Users\Admin\AppData\Roaming\Python\Python312\site-packages\sqlalchemy\engine\base.py", line 3302, in raw_connection
    return self.pool.connect()
           ^^^^^^^^^^^^^^^^^^^
  File "C:\Users\Admin\AppData\Roaming\Python\Python312\site-packages\sqlalchemy\pool\base.py", line 449, in connect
    return _ConnectionFairy._checkout(self)
           ^^^^^^^^^^^^^^^^^^^^^^^^^^^^^^^^
  File "C:\Users\Admin\AppData\Roaming\Python\Python312\site-packages\sqlalchemy\pool\base.py", line 1263, in _checkout
    fairy = _ConnectionRecord.checkout(pool)
            ^^^^^^^^^^^^^^^^^^^^^^^^^^^^^^^^
  File "C:\Users\Admin\AppData\Roaming\Python\Python312\site-packages\sqlalchemy\pool\base.py", line 712, in checkout
    rec = pool._do_get()
          ^^^^^^^^^^^^^^
  File "C:\Users\Admin\AppData\Roaming\Python\Python312\site-packages\sqlalchemy\pool\impl.py", line 179, in _do_get
    with util.safe_reraise():
  File "C:\Users\Admin\AppData\Roaming\Python\Python312\site-packages\sqlalchemy\util\langhelpers.py", line 146, in __exit__
    raise exc_value.with_traceback(exc_tb)
  File "C:\Users\Admin\AppData\Roaming\Python\Python312\site-packages\sqlalchemy\pool\impl.py", line 177, in _do_get
    return self._create_connection()
           ^^^^^^^^^^^^^^^^^^^^^^^^^
  File "C:\Users\Admin\AppData\Roaming\Python\Python312\site-packages\sqlalchemy\pool\base.py", line 390, in _create_connection
    return _ConnectionRecord(self)
           ^^^^^^^^^^^^^^^^^^^^^^^
  File "C:\Users\Admin\AppData\Roaming\Python\Python312\site-packages\sqlalchemy\pool\base.py", line 674, in __init__
    self.__connect()
  File "C:\Users\Admin\AppData\Roaming\Python\Python312\site-packages\sqlalchemy\pool\base.py", line 900, in __connect
    with util.safe_reraise():
  File "C:\Users\Admin\AppData\Roaming\Python\Python312\site-packages\sqlalchemy\util\langhelpers.py", line 146, in __exit__
    raise exc_value.with_traceback(exc_tb)
  File "C:\Users\Admin\AppData\Roaming\Python\Python312\site-packages\sqlalchemy\pool\base.py", line 896, in __connect
    self.dbapi_connection = connection = pool._invoke_creator(self)
                                         ^^^^^^^^^^^^^^^^^^^^^^^^^^
  File "C:\Users\Admin\AppData\Roaming\Python\Python312\site-packages\sqlalchemy\engine\create.py", line 643, in connect
    return dialect.connect(*cargs, **cparams)
           ^^^^^^^^^^^^^^^^^^^^^^^^^^^^^^^^^^
  File "C:\Users\Admin\AppData\Roaming\Python\Python312\site-packages\sqlalchemy\engine\default.py", line 621, in connect
    return self.loaded_dbapi.connect(*cargs, **cparams)
           ^^^^^^^^^^^^^^^^^^^^^^^^^^^^^^^^^^^^^^^^^^^^
  File "C:\Users\Admin\AppData\Roaming\Python\Python312\site-packages\sqlalchemy\dialects\postgresql\asyncpg.py", line 953, in connect
    await_only(creator_fn(*arg, **kw)),
    ^^^^^^^^^^^^^^^^^^^^^^^^^^^^^^^^^^
  File "C:\Users\Admin\AppData\Roaming\Python\Python312\site-packages\sqlalchemy\util\_concurrency_py3k.py", line 132, in await_only
    return current.parent.switch(awaitable)  # type: ignore[no-any-return,attr-defined] # noqa: E501
           ^^^^^^^^^^^^^^^^^^^^^^^^^^^^^^^^
  File "C:\Users\Admin\AppData\Roaming\Python\Python312\site-packages\sqlalchemy\util\_concurrency_py3k.py", line 196, in greenlet_spawn
    value = await result
            ^^^^^^^^^^^^
  File "C:\Users\Admin\AppData\Roaming\Python\Python312\site-packages\asyncpg\connection.py", line 2329, in connect
    return await connect_utils._connect(
           ^^^^^^^^^^^^^^^^^^^^^^^^^^^^^
  File "C:\Users\Admin\AppData\Roaming\Python\Python312\site-packages\asyncpg\connect_utils.py", line 1017, in _connect
    raise last_error or exceptions.TargetServerAttributeNotMatched(
  File "C:\Users\Admin\AppData\Roaming\Python\Python312\site-packages\asyncpg\connect_utils.py", line 991, in _connect
    conn = await _connect_addr(
           ^^^^^^^^^^^^^^^^^^^^
  File "C:\Users\Admin\AppData\Roaming\Python\Python312\site-packages\asyncpg\connect_utils.py", line 828, in _connect_addr
    return await __connect_addr(params, True, *args)
           ^^^^^^^^^^^^^^^^^^^^^^^^^^^^^^^^^^^^^^^^^
  File "C:\Users\Admin\AppData\Roaming\Python\Python312\site-packages\asyncpg\connect_utils.py", line 873, in __connect_addr
    tr, pr = await connector
             ^^^^^^^^^^^^^^^
  File "C:\Users\Admin\AppData\Roaming\Python\Python312\site-packages\asyncpg\connect_utils.py", line 744, in _create_ssl_connection
    tr, pr = await loop.create_connection(
             ^^^^^^^^^^^^^^^^^^^^^^^^^^^^^
  File "D:\installed_software\anaconda3\envs\myenv3\Lib\asyncio\base_events.py", line 1130, in create_connection
    raise OSError('Multiple exceptions: {}'.format(
OSError: Multiple exceptions: [Errno 10061] Connect call failed ('::1', 5432, 0, 0), [Errno 10061] Connect call failed ('127.0.0.1', 5432)

During handling of the above exception, another exception occurred:

Traceback (most recent call last):
  File "D:\Projects\Fast_API\blog_app\backend\app\core\database.py", line 21, in get_db
    yield session
  File "C:\Users\Admin\AppData\Roaming\Python\Python312\site-packages\fastapi\routing.py", line 278, in app
    raw_response = await run_endpoint_function(
                   ^^^^^^^^^^^^^^^^^^^^^^^^^^^^
  File "C:\Users\Admin\AppData\Roaming\Python\Python312\site-packages\fastapi\routing.py", line 191, in run_endpoint_function
    return await dependant.call(**values)
           ^^^^^^^^^^^^^^^^^^^^^^^^^^^^^^
  File "D:\Projects\Fast_API\blog_app\backend\app\routers\subcategories.py", line 166, in get_subcategories_for_category
    raise e
  File "D:\Projects\Fast_API\blog_app\backend\app\routers\subcategories.py", line 144, in get_subcategories_for_category
    result = await get_subcategories_by_category_id(db, category_id, skip, limit)
             ^^^^^^^^^^^^^^^^^^^^^^^^^^^^^^^^^^^^^^^^^^^^^^^^^^^^^^^^^^^^^^^^^^^^
  File "D:\Projects\Fast_API\blog_app\backend\app\services\subcategories.py", line 176, in get_subcategories_by_category_id
    raise HTTPException(status_code=500, detail="Failed to fetch subcategories for the category.")
fastapi.exceptions.HTTPException: 500: Failed to fetch subcategories for the category.
ERROR 2024-09-24 11:00:15 root Error fetching subcategories for category ID 1: Multiple exceptions: [Errno 10061] Connect call failed ('::1', 5432, 0, 0), [Errno 10061] Connect call failed ('127.0.0.1', 5432)
Traceback (most recent call last):
  File "D:\Projects\Fast_API\blog_app\backend\app\services\subcategories.py", line 143, in get_subcategories_by_category_id
    category_result = await db.execute(select(Category).where(Category.id == category_id))
                      ^^^^^^^^^^^^^^^^^^^^^^^^^^^^^^^^^^^^^^^^^^^^^^^^^^^^^^^^^^^^^^^^^^^^
  File "C:\Users\Admin\AppData\Roaming\Python\Python312\site-packages\sqlalchemy\ext\asyncio\session.py", line 461, in execute
    result = await greenlet_spawn(
             ^^^^^^^^^^^^^^^^^^^^^
  File "C:\Users\Admin\AppData\Roaming\Python\Python312\site-packages\sqlalchemy\util\_concurrency_py3k.py", line 201, in greenlet_spawn
    result = context.throw(*sys.exc_info())
             ^^^^^^^^^^^^^^^^^^^^^^^^^^^^^^
  File "C:\Users\Admin\AppData\Roaming\Python\Python312\site-packages\sqlalchemy\orm\session.py", line 2362, in execute
    return self._execute_internal(
           ^^^^^^^^^^^^^^^^^^^^^^^
  File "C:\Users\Admin\AppData\Roaming\Python\Python312\site-packages\sqlalchemy\orm\session.py", line 2237, in _execute_internal
    conn = self._connection_for_bind(bind)
           ^^^^^^^^^^^^^^^^^^^^^^^^^^^^^^^
  File "C:\Users\Admin\AppData\Roaming\Python\Python312\site-packages\sqlalchemy\orm\session.py", line 2106, in _connection_for_bind
    return trans._connection_for_bind(engine, execution_options)
           ^^^^^^^^^^^^^^^^^^^^^^^^^^^^^^^^^^^^^^^^^^^^^^^^^^^^^
  File "<string>", line 2, in _connection_for_bind
  File "C:\Users\Admin\AppData\Roaming\Python\Python312\site-packages\sqlalchemy\orm\state_changes.py", line 139, in _go
    ret_value = fn(self, *arg, **kw)
                ^^^^^^^^^^^^^^^^^^^^
  File "C:\Users\Admin\AppData\Roaming\Python\Python312\site-packages\sqlalchemy\orm\session.py", line 1189, in _connection_for_bind
    conn = bind.connect()
           ^^^^^^^^^^^^^^
  File "C:\Users\Admin\AppData\Roaming\Python\Python312\site-packages\sqlalchemy\engine\base.py", line 3278, in connect
    return self._connection_cls(self)
           ^^^^^^^^^^^^^^^^^^^^^^^^^^
  File "C:\Users\Admin\AppData\Roaming\Python\Python312\site-packages\sqlalchemy\engine\base.py", line 146, in __init__
    self._dbapi_connection = engine.raw_connection()
                             ^^^^^^^^^^^^^^^^^^^^^^^
  File "C:\Users\Admin\AppData\Roaming\Python\Python312\site-packages\sqlalchemy\engine\base.py", line 3302, in raw_connection
    return self.pool.connect()
           ^^^^^^^^^^^^^^^^^^^
  File "C:\Users\Admin\AppData\Roaming\Python\Python312\site-packages\sqlalchemy\pool\base.py", line 449, in connect
    return _ConnectionFairy._checkout(self)
           ^^^^^^^^^^^^^^^^^^^^^^^^^^^^^^^^
  File "C:\Users\Admin\AppData\Roaming\Python\Python312\site-packages\sqlalchemy\pool\base.py", line 1263, in _checkout
    fairy = _ConnectionRecord.checkout(pool)
            ^^^^^^^^^^^^^^^^^^^^^^^^^^^^^^^^
  File "C:\Users\Admin\AppData\Roaming\Python\Python312\site-packages\sqlalchemy\pool\base.py", line 712, in checkout
    rec = pool._do_get()
          ^^^^^^^^^^^^^^
  File "C:\Users\Admin\AppData\Roaming\Python\Python312\site-packages\sqlalchemy\pool\impl.py", line 179, in _do_get
    with util.safe_reraise():
  File "C:\Users\Admin\AppData\Roaming\Python\Python312\site-packages\sqlalchemy\util\langhelpers.py", line 146, in __exit__
    raise exc_value.with_traceback(exc_tb)
  File "C:\Users\Admin\AppData\Roaming\Python\Python312\site-packages\sqlalchemy\pool\impl.py", line 177, in _do_get
    return self._create_connection()
           ^^^^^^^^^^^^^^^^^^^^^^^^^
  File "C:\Users\Admin\AppData\Roaming\Python\Python312\site-packages\sqlalchemy\pool\base.py", line 390, in _create_connection
    return _ConnectionRecord(self)
           ^^^^^^^^^^^^^^^^^^^^^^^
  File "C:\Users\Admin\AppData\Roaming\Python\Python312\site-packages\sqlalchemy\pool\base.py", line 674, in __init__
    self.__connect()
  File "C:\Users\Admin\AppData\Roaming\Python\Python312\site-packages\sqlalchemy\pool\base.py", line 900, in __connect
    with util.safe_reraise():
  File "C:\Users\Admin\AppData\Roaming\Python\Python312\site-packages\sqlalchemy\util\langhelpers.py", line 146, in __exit__
    raise exc_value.with_traceback(exc_tb)
  File "C:\Users\Admin\AppData\Roaming\Python\Python312\site-packages\sqlalchemy\pool\base.py", line 896, in __connect
    self.dbapi_connection = connection = pool._invoke_creator(self)
                                         ^^^^^^^^^^^^^^^^^^^^^^^^^^
  File "C:\Users\Admin\AppData\Roaming\Python\Python312\site-packages\sqlalchemy\engine\create.py", line 643, in connect
    return dialect.connect(*cargs, **cparams)
           ^^^^^^^^^^^^^^^^^^^^^^^^^^^^^^^^^^
  File "C:\Users\Admin\AppData\Roaming\Python\Python312\site-packages\sqlalchemy\engine\default.py", line 621, in connect
    return self.loaded_dbapi.connect(*cargs, **cparams)
           ^^^^^^^^^^^^^^^^^^^^^^^^^^^^^^^^^^^^^^^^^^^^
  File "C:\Users\Admin\AppData\Roaming\Python\Python312\site-packages\sqlalchemy\dialects\postgresql\asyncpg.py", line 953, in connect
    await_only(creator_fn(*arg, **kw)),
    ^^^^^^^^^^^^^^^^^^^^^^^^^^^^^^^^^^
  File "C:\Users\Admin\AppData\Roaming\Python\Python312\site-packages\sqlalchemy\util\_concurrency_py3k.py", line 132, in await_only
    return current.parent.switch(awaitable)  # type: ignore[no-any-return,attr-defined] # noqa: E501
           ^^^^^^^^^^^^^^^^^^^^^^^^^^^^^^^^
  File "C:\Users\Admin\AppData\Roaming\Python\Python312\site-packages\sqlalchemy\util\_concurrency_py3k.py", line 196, in greenlet_spawn
    value = await result
            ^^^^^^^^^^^^
  File "C:\Users\Admin\AppData\Roaming\Python\Python312\site-packages\asyncpg\connection.py", line 2329, in connect
    return await connect_utils._connect(
           ^^^^^^^^^^^^^^^^^^^^^^^^^^^^^
  File "C:\Users\Admin\AppData\Roaming\Python\Python312\site-packages\asyncpg\connect_utils.py", line 1017, in _connect
    raise last_error or exceptions.TargetServerAttributeNotMatched(
  File "C:\Users\Admin\AppData\Roaming\Python\Python312\site-packages\asyncpg\connect_utils.py", line 991, in _connect
    conn = await _connect_addr(
           ^^^^^^^^^^^^^^^^^^^^
  File "C:\Users\Admin\AppData\Roaming\Python\Python312\site-packages\asyncpg\connect_utils.py", line 828, in _connect_addr
    return await __connect_addr(params, True, *args)
           ^^^^^^^^^^^^^^^^^^^^^^^^^^^^^^^^^^^^^^^^^
  File "C:\Users\Admin\AppData\Roaming\Python\Python312\site-packages\asyncpg\connect_utils.py", line 873, in __connect_addr
    tr, pr = await connector
             ^^^^^^^^^^^^^^^
  File "C:\Users\Admin\AppData\Roaming\Python\Python312\site-packages\asyncpg\connect_utils.py", line 744, in _create_ssl_connection
    tr, pr = await loop.create_connection(
             ^^^^^^^^^^^^^^^^^^^^^^^^^^^^^
  File "D:\installed_software\anaconda3\envs\myenv3\Lib\asyncio\base_events.py", line 1130, in create_connection
    raise OSError('Multiple exceptions: {}'.format(
OSError: Multiple exceptions: [Errno 10061] Connect call failed ('::1', 5432, 0, 0), [Errno 10061] Connect call failed ('127.0.0.1', 5432)
ERROR 2024-09-24 11:00:15 root HTTPException: Failed to fetch subcategories for the category. (Category ID: 1)
ERROR 2024-09-24 11:00:15 root Unexpected error: 500: Failed to fetch subcategories for the category.
Traceback (most recent call last):
  File "D:\Projects\Fast_API\blog_app\backend\app\services\subcategories.py", line 143, in get_subcategories_by_category_id
    category_result = await db.execute(select(Category).where(Category.id == category_id))
                      ^^^^^^^^^^^^^^^^^^^^^^^^^^^^^^^^^^^^^^^^^^^^^^^^^^^^^^^^^^^^^^^^^^^^
  File "C:\Users\Admin\AppData\Roaming\Python\Python312\site-packages\sqlalchemy\ext\asyncio\session.py", line 461, in execute
    result = await greenlet_spawn(
             ^^^^^^^^^^^^^^^^^^^^^
  File "C:\Users\Admin\AppData\Roaming\Python\Python312\site-packages\sqlalchemy\util\_concurrency_py3k.py", line 201, in greenlet_spawn
    result = context.throw(*sys.exc_info())
             ^^^^^^^^^^^^^^^^^^^^^^^^^^^^^^
  File "C:\Users\Admin\AppData\Roaming\Python\Python312\site-packages\sqlalchemy\orm\session.py", line 2362, in execute
    return self._execute_internal(
           ^^^^^^^^^^^^^^^^^^^^^^^
  File "C:\Users\Admin\AppData\Roaming\Python\Python312\site-packages\sqlalchemy\orm\session.py", line 2237, in _execute_internal
    conn = self._connection_for_bind(bind)
           ^^^^^^^^^^^^^^^^^^^^^^^^^^^^^^^
  File "C:\Users\Admin\AppData\Roaming\Python\Python312\site-packages\sqlalchemy\orm\session.py", line 2106, in _connection_for_bind
    return trans._connection_for_bind(engine, execution_options)
           ^^^^^^^^^^^^^^^^^^^^^^^^^^^^^^^^^^^^^^^^^^^^^^^^^^^^^
  File "<string>", line 2, in _connection_for_bind
  File "C:\Users\Admin\AppData\Roaming\Python\Python312\site-packages\sqlalchemy\orm\state_changes.py", line 139, in _go
    ret_value = fn(self, *arg, **kw)
                ^^^^^^^^^^^^^^^^^^^^
  File "C:\Users\Admin\AppData\Roaming\Python\Python312\site-packages\sqlalchemy\orm\session.py", line 1189, in _connection_for_bind
    conn = bind.connect()
           ^^^^^^^^^^^^^^
  File "C:\Users\Admin\AppData\Roaming\Python\Python312\site-packages\sqlalchemy\engine\base.py", line 3278, in connect
    return self._connection_cls(self)
           ^^^^^^^^^^^^^^^^^^^^^^^^^^
  File "C:\Users\Admin\AppData\Roaming\Python\Python312\site-packages\sqlalchemy\engine\base.py", line 146, in __init__
    self._dbapi_connection = engine.raw_connection()
                             ^^^^^^^^^^^^^^^^^^^^^^^
  File "C:\Users\Admin\AppData\Roaming\Python\Python312\site-packages\sqlalchemy\engine\base.py", line 3302, in raw_connection
    return self.pool.connect()
           ^^^^^^^^^^^^^^^^^^^
  File "C:\Users\Admin\AppData\Roaming\Python\Python312\site-packages\sqlalchemy\pool\base.py", line 449, in connect
    return _ConnectionFairy._checkout(self)
           ^^^^^^^^^^^^^^^^^^^^^^^^^^^^^^^^
  File "C:\Users\Admin\AppData\Roaming\Python\Python312\site-packages\sqlalchemy\pool\base.py", line 1263, in _checkout
    fairy = _ConnectionRecord.checkout(pool)
            ^^^^^^^^^^^^^^^^^^^^^^^^^^^^^^^^
  File "C:\Users\Admin\AppData\Roaming\Python\Python312\site-packages\sqlalchemy\pool\base.py", line 712, in checkout
    rec = pool._do_get()
          ^^^^^^^^^^^^^^
  File "C:\Users\Admin\AppData\Roaming\Python\Python312\site-packages\sqlalchemy\pool\impl.py", line 179, in _do_get
    with util.safe_reraise():
  File "C:\Users\Admin\AppData\Roaming\Python\Python312\site-packages\sqlalchemy\util\langhelpers.py", line 146, in __exit__
    raise exc_value.with_traceback(exc_tb)
  File "C:\Users\Admin\AppData\Roaming\Python\Python312\site-packages\sqlalchemy\pool\impl.py", line 177, in _do_get
    return self._create_connection()
           ^^^^^^^^^^^^^^^^^^^^^^^^^
  File "C:\Users\Admin\AppData\Roaming\Python\Python312\site-packages\sqlalchemy\pool\base.py", line 390, in _create_connection
    return _ConnectionRecord(self)
           ^^^^^^^^^^^^^^^^^^^^^^^
  File "C:\Users\Admin\AppData\Roaming\Python\Python312\site-packages\sqlalchemy\pool\base.py", line 674, in __init__
    self.__connect()
  File "C:\Users\Admin\AppData\Roaming\Python\Python312\site-packages\sqlalchemy\pool\base.py", line 900, in __connect
    with util.safe_reraise():
  File "C:\Users\Admin\AppData\Roaming\Python\Python312\site-packages\sqlalchemy\util\langhelpers.py", line 146, in __exit__
    raise exc_value.with_traceback(exc_tb)
  File "C:\Users\Admin\AppData\Roaming\Python\Python312\site-packages\sqlalchemy\pool\base.py", line 896, in __connect
    self.dbapi_connection = connection = pool._invoke_creator(self)
                                         ^^^^^^^^^^^^^^^^^^^^^^^^^^
  File "C:\Users\Admin\AppData\Roaming\Python\Python312\site-packages\sqlalchemy\engine\create.py", line 643, in connect
    return dialect.connect(*cargs, **cparams)
           ^^^^^^^^^^^^^^^^^^^^^^^^^^^^^^^^^^
  File "C:\Users\Admin\AppData\Roaming\Python\Python312\site-packages\sqlalchemy\engine\default.py", line 621, in connect
    return self.loaded_dbapi.connect(*cargs, **cparams)
           ^^^^^^^^^^^^^^^^^^^^^^^^^^^^^^^^^^^^^^^^^^^^
  File "C:\Users\Admin\AppData\Roaming\Python\Python312\site-packages\sqlalchemy\dialects\postgresql\asyncpg.py", line 953, in connect
    await_only(creator_fn(*arg, **kw)),
    ^^^^^^^^^^^^^^^^^^^^^^^^^^^^^^^^^^
  File "C:\Users\Admin\AppData\Roaming\Python\Python312\site-packages\sqlalchemy\util\_concurrency_py3k.py", line 132, in await_only
    return current.parent.switch(awaitable)  # type: ignore[no-any-return,attr-defined] # noqa: E501
           ^^^^^^^^^^^^^^^^^^^^^^^^^^^^^^^^
  File "C:\Users\Admin\AppData\Roaming\Python\Python312\site-packages\sqlalchemy\util\_concurrency_py3k.py", line 196, in greenlet_spawn
    value = await result
            ^^^^^^^^^^^^
  File "C:\Users\Admin\AppData\Roaming\Python\Python312\site-packages\asyncpg\connection.py", line 2329, in connect
    return await connect_utils._connect(
           ^^^^^^^^^^^^^^^^^^^^^^^^^^^^^
  File "C:\Users\Admin\AppData\Roaming\Python\Python312\site-packages\asyncpg\connect_utils.py", line 1017, in _connect
    raise last_error or exceptions.TargetServerAttributeNotMatched(
  File "C:\Users\Admin\AppData\Roaming\Python\Python312\site-packages\asyncpg\connect_utils.py", line 991, in _connect
    conn = await _connect_addr(
           ^^^^^^^^^^^^^^^^^^^^
  File "C:\Users\Admin\AppData\Roaming\Python\Python312\site-packages\asyncpg\connect_utils.py", line 828, in _connect_addr
    return await __connect_addr(params, True, *args)
           ^^^^^^^^^^^^^^^^^^^^^^^^^^^^^^^^^^^^^^^^^
  File "C:\Users\Admin\AppData\Roaming\Python\Python312\site-packages\asyncpg\connect_utils.py", line 873, in __connect_addr
    tr, pr = await connector
             ^^^^^^^^^^^^^^^
  File "C:\Users\Admin\AppData\Roaming\Python\Python312\site-packages\asyncpg\connect_utils.py", line 744, in _create_ssl_connection
    tr, pr = await loop.create_connection(
             ^^^^^^^^^^^^^^^^^^^^^^^^^^^^^
  File "D:\installed_software\anaconda3\envs\myenv3\Lib\asyncio\base_events.py", line 1130, in create_connection
    raise OSError('Multiple exceptions: {}'.format(
OSError: Multiple exceptions: [Errno 10061] Connect call failed ('::1', 5432, 0, 0), [Errno 10061] Connect call failed ('127.0.0.1', 5432)

During handling of the above exception, another exception occurred:

Traceback (most recent call last):
  File "D:\Projects\Fast_API\blog_app\backend\app\core\database.py", line 21, in get_db
    yield session
  File "C:\Users\Admin\AppData\Roaming\Python\Python312\site-packages\fastapi\routing.py", line 278, in app
    raw_response = await run_endpoint_function(
                   ^^^^^^^^^^^^^^^^^^^^^^^^^^^^
  File "C:\Users\Admin\AppData\Roaming\Python\Python312\site-packages\fastapi\routing.py", line 191, in run_endpoint_function
    return await dependant.call(**values)
           ^^^^^^^^^^^^^^^^^^^^^^^^^^^^^^
  File "D:\Projects\Fast_API\blog_app\backend\app\routers\subcategories.py", line 175, in get_subcategories_for_category
    raise e
  File "D:\Projects\Fast_API\blog_app\backend\app\routers\subcategories.py", line 145, in get_subcategories_for_category
    result = await get_subcategories_by_category_id(db, category_id, skip, limit)
             ^^^^^^^^^^^^^^^^^^^^^^^^^^^^^^^^^^^^^^^^^^^^^^^^^^^^^^^^^^^^^^^^^^^^
  File "D:\Projects\Fast_API\blog_app\backend\app\services\subcategories.py", line 181, in get_subcategories_by_category_id
    raise HTTPException(
fastapi.exceptions.HTTPException: 500: Failed to fetch subcategories for the category.
